Workbook

Sheet README
A1: Assignment 1910090826 — Analytics Workbook (Option A: Public Sector Healthcare)
A2: Healthcare Infrastructure & Resource Planning · public_health_2021_2024.csv · Jan 2021 – Dec 2024 (48 months)
A4: Sheet | B4: Unit | C4: What it contains
A5: Data | B5: – | C5: Cleaned dataset + calculated fields (Year, Quarter, Season, Winter dummy, $/ER visit, ER visits per flu case, ICU>85% flag)
A6: Descriptive_Stats | B6: Unit 4 | C6: Mean, median, SD, variance, CV, quartiles, IQR, skewness, kurtosis, IQR fences and outlier counts (native formulas)
A7: Frequency | B7: Unit 4 | C7: Frequency distributions (COUNTIFS) with relative/cumulative % and histogram charts
A8: Pivot_Tables | B8: Unit 4 | C8: Native PivotTables: ER visits Quarter×Year, % of column total, YoY % difference, Season×Year ICU, annual KPI pivot
A9: Pivot_Formulas | B9: Unit 4 | C9: Formula cross-tabs with calculated fields: % of column total, YoY growth, $/visit, ICU breach counts, Month×Year heat map
A10: Correlation | B10: Unit 4 | C10: CORREL matrix heat map (colour scale) + significance (p-value) matrix
A11: Anomalies | B11: Unit 4 | C11: z-scores, irregular component, ICU threshold breaches, month-on-month change and anomaly flags
A12: SLR | B12: Unit 5 | C12: Simple linear regression ER_Visits ~ Flu_Resp_Cases in Analysis ToolPak layout (live LINEST formulas) + fitted-line chart
A13: MLR_Full | B13: Unit 5 | C13: MLR: Flu + Population density + Vaccination + Winter dummy; ANOVA, coefficients, p-values, VIF, JB normality, Breusch-Pagan, Durbin-Watson
A14: MLR_Refined | B14: Unit 5 | C14: Refined MLR after VIF diagnosis (Flu + Population density + Winter dummy)
A15: Decomposition | B15: Unit 6 | C15: Classical decomposition (2×12 centred MA, ratio-to-MA seasonal indices), additive vs multiplicative comparison
... A20: Forecast_2025 | B20: Sec. 4 | C20: Prediction intervals, staffing index, ICU bed requirement, budget reserve and severe-flu-season stress test
A22: Colour key: yellow cells = inputs/assumptions you may change (all dependent formulas update); green cells = key results.
A23: Holt-Winters smoothing parameters were optimised in Python (min SSE). To re-optimise in Excel: Data ▸ Solver ▸ minimise the SSE cell by changing α, β, γ (constraints 0.01–0.99).
A24: Shapiro-Wilk, White and HAC (Newey-West) tests, and the rolling-origin prediction intervals, are computed in the companion notebook 1910090826_Analytics_Workbook.ipynb.
A25: ICU forecasts and the flu-case forecast for 2025 are produced with the same Holt-Winters procedure in the notebook and entered on Forecast_2025 as inputs.

Sheet Data
A1: Month | B1: Date | C1: Year | D1: Quarter | E1: MonthNum | F1: Season | G1: Winter | H1: t | I1: ER_Visits | J1: ICU_Util_Rate | K1: Pub_Health_Exp | L1: Pop_Density_Idx | M1: Vacc_Coverage | N1: Flu_Resp_Cases | O1: Exp_per_ER_Visit | P1: ER_per_Flu_Case | Q1: ICU_Over_85 | R1: Vacc_Change_pp
A2: 2021-01 | B2: 44197 | C2: =YEAR(B2) -> 2021 | D2: ="Q"&ROUNDUP(MONTH(B2)/3,0) -> Q1 | E2: =MONTH(B2) -> 1 | F2: =CHOOSE(E2,"Winter","Winter","Spring","Spring","Spring","Summer","Summer","Summer","Autumn","Autumn","Autumn","Winter") -> Winter | G2: =IF(F2="Winter",1,0) -> 1 | H2: 1 | I2: 4820 | J2: 78.4 | K2: 1250000 | L2: 102.3 | M2: 61.2 | N2: 1340 | O2: =K2/I2 -> 259.3361 | P2: =I2/N2 -> 3.5970149 | Q2: =IF(J2>85,1,0) -> 0
A3: 2021-02 | B3: 44228 | C3: =YEAR(B3) -> 2021 | D3: ="Q"&ROUNDUP(MONTH(B3)/3,0) -> Q1 | E3: =MONTH(B3) -> 2 | F3: =CHOOSE(E3,"Winter","Winter","Spring","Spring","Spring","Summer","Summer","Summer","Autumn","Autumn","Autumn","Winter") -> Winter | G3: =IF(F3="Winter",1,0) -> 1 | H3: 2 | I3: 4510 | J3: 74.1 | K3: 1180000 | L3: 102.5 | M3: 63.8 | N3: 1180 | O3: =K3/I3 -> 261.6408 | P3: =I3/N3 -> 3.8220339 | Q3: =IF(J3>85,1,0) -> 0 | R3: =M3-M2 -> 2.6
A4: 2021-03 | B4: 44256 | C4: =YEAR(B4) -> 2021 | D4: ="Q"&ROUNDUP(MONTH(B4)/3,0) -> Q1 | E4: =MONTH(B4) -> 3 | F4: =CHOOSE(E4,"Winter","Winter","Spring","Spring","Spring","Summer","Summer","Summer","Autumn","Autumn","Autumn","Winter") -> Spring | G4: =IF(F4="Winter",1,0) -> 0 | H4: 3 | I4: 4180 | J4: 69.5 | K4: 1120000 | L4: 102.8 | M4: 66.1 | N4: 980 | O4: =K4/I4 -> 267.94258 | P4: =I4/N4 -> 4.2653061 | Q4: =IF(J4>85,1,0) -> 0 | R4: =M4-M3 -> 2.3
A5: 2021-04 | B5: 44287 | C5: =YEAR(B5) -> 2021 | D5: ="Q"&ROUNDUP(MONTH(B5)/3,0) -> Q2 | E5: =MONTH(B5) -> 4 | F5: =CHOOSE(E5,"Winter","Winter","Spring","Spring","Spring","Summer","Summer","Summer","Autumn","Autumn","Autumn","Winter") -> Spring | G5: =IF(F5="Winter",1,0) -> 0 | H5: 4 | I5: 3920 | J5: 64.2 | K5: 1080000 | L5: 103 | M5: 68.4 | N5: 820 | O5: =K5/I5 -> 275.5102 | P5: =I5/N5 -> 4.7804878 | Q5: =IF(J5>85,1,0) -> 0 | R5: =M5-M4 -> 2.3
A6: 2021-05 | B6: 44317 | C6: =YEAR(B6) -> 2021 | D6: ="Q"&ROUNDUP(MONTH(B6)/3,0) -> Q2 | E6: =MONTH(B6) -> 5 | F6: =CHOOSE(E6,"Winter","Winter","Spring","Spring","Spring","Summer","Summer","Summer","Autumn","Autumn","Autumn","Winter") -> Spring | G6: =IF(F6="Winter",1,0) -> 0 | H6: 5 | I6: 3710 | J6: 61.8 | K6: 1050000 | L6: 103.2 | M6: 70.2 | N6: 740 | O6: =K6/I6 -> 283.01887 | P6: =I6/N6 -> 5.0135135 | Q6: =IF(J6>85,1,0) -> 0 | R6: =M6-M5 -> 1.8
A7: 2021-06 | B7: 44348 | C7: =YEAR(B7) -> 2021 | D7: ="Q"&ROUNDUP(MONTH(B7)/3,0) -> Q2 | E7: =MONTH(B7) -> 6 | F7: =CHOOSE(E7,"Winter","Winter","Spring","Spring","Spring","Summer","Summer","Summer","Autumn","Autumn","Autumn","Winter") -> Summer | G7: =IF(F7="Winter",1,0) -> 0 | H7: 6 | I7: 3580 | J7: 59.4 | K7: 1020000 | L7: 103.4 | M7: 71.5 | N7: 690 | O7: =K7/I7 -> 284.9162 | P7: =I7/N7 -> 5.1884058 | Q7: =IF(J7>85,1,0) -> 0 | R7: =M7-M6 -> 1.3
A8: 2021-07 | B8: 44378 | C8: =YEAR(B8) -> 2021 | D8: ="Q"&ROUNDUP(MONTH(B8)/3,0) -> Q3 | E8: =MONTH(B8) -> 7 | F8: =CHOOSE(E8,"Winter","Winter","Spring","Spring","Spring","Summer","Summer","Summer","Autumn","Autumn","Autumn","Winter") -> Summer | G8: =IF(F8="Winter",1,0) -> 0 | H8: 7 | I8: 3620 | J8: 60.1 | K8: 1040000 | L8: 103.6 | M8: 72 | N8: 720 | O8: =K8/I8 -> 287.29282 | P8: =I8/N8 -> 5.0277778 | Q8: =IF(J8>85,1,0) -> 0 | R8: =M8-M7 -> 0.5
A9: 2021-08 | B9: 44409 | C9: =YEAR(B9) -> 2021 | D9: ="Q"&ROUNDUP(MONTH(B9)/3,0) -> Q3 | E9: =MONTH(B9) -> 8 | F9: =CHOOSE(E9,"Winter","Winter","Spring","Spring","Spring","Summer","Summer","Summer","Autumn","Autumn","Autumn","Winter") -> Summer | G9: =IF(F9="Winter",1,0) -> 0 | H9: 8 | I9: 3790 | J9: 63.7 | K9: 1070000 | L9: 103.8 | M9: 72.6 | N9: 810 | O9: =K9/I9 -> 282.3219 | P9: =I9/N9 -> 4.6790123 | Q9: =IF(J9>85,1,0) -> 0 | R9: =M9-M8 -> 0.6
A10: 2021-09 | B10: 44440 | C10: =YEAR(B10) -> 2021 | D10: ="Q"&ROUNDUP(MONTH(B10)/3,0) -> Q3 | E10: =MONTH(B10) -> 9 | F10: =CHOOSE(E10,"Winter","Winter","Spring","Spring","Spring","Summer","Summer","Summer","Autumn","Autumn","Autumn","Winter") -> Autumn | G10: =IF(F10="Winter",1,0) -> 0 | H10: 9 | I10: 4120 | J10: 68.9 | K10: 1130000 | L10: 104 | M10: 73.1 | N10: 1020 | O10: =K10/I10 -> 274.27184 | P10: =I10/N10 -> 4.0392157 | Q10: =IF(J10>85,1,0) -> 0 | R10: =M10-M9 -> 0.5
A11: 2021-10 | B11: 44470 | C11: =YEAR(B11) -> 2021 | D11: ="Q"&ROUNDUP(MONTH(B11)/3,0) -> Q4 | E11: =MONTH(B11) -> 10 | F11: =CHOOSE(E11,"Winter","Winter","Spring","Spring","Spring","Summer","Summer","Summer","Autumn","Autumn","Autumn","Winter") -> Autumn | G11: =IF(F11="Winter",1,0) -> 0 | H11: 10 | I11: 4480 | J11: 73.2 | K11: 1190000 | L11: 104.2 | M11: 73.5 | N11: 1190 | O11: =K11/I11 -> 265.625 | P11: =I11/N11 -> 3.7647059 | Q11: =IF(J11>85,1,0) -> 0 | R11: =M11-M10 -> 0.4
A12: 2021-11 | B12: 44501 | C12: =YEAR(B12) -> 2021 | D12: ="Q"&ROUNDUP(MONTH(B12)/3,0) -> Q4 | E12: =MONTH(B12) -> 11 | F12: =CHOOSE(E12,"Winter","Winter","Spring","Spring","Spring","Summer","Summer","Summer","Autumn","Autumn","Autumn","Winter") -> Autumn | G12: =IF(F12="Winter",1,0) -> 0 | H12: 11 | I12: 4910 | J12: 79.8 | K12: 1270000 | L12: 104.4 | M12: 73.8 | N12: 1420 | O12: =K12/I12 -> 258.6558 | P12: =I12/N12 -> 3.4577465 | Q12: =IF(J12>85,1,0) -> 0 | R12: =M12-M11 -> 0.3
A13: 2021-12 | B13: 44531 | C13: =YEAR(B13) -> 2021 | D13: ="Q"&ROUNDUP(MONTH(B13)/3,0) -> Q4 | E13: =MONTH(B13) -> 12 | F13: =CHOOSE(E13,"Winter","Winter","Spring","Spring","Spring","Summer","Summer","Summer","Autumn","Autumn","Autumn","Winter") -> Winter | G13: =IF(F13="Winter",1,0) -> 1 | H13: 12 | I13: 5340 | J13: 86.2 | K13: 1360000 | L13: 104.6 | M13: 74 | N13: 1680 | O13: =K13/I13 -> 254.68165 | P13: =I13/N13 -> 3.1785714 | Q13: =IF(J13>85,1,0) -> 1 | R13: =M13-M12 -> 0.2
A14: 2022-01 | B14: 44562 | C14: =YEAR(B14) -> 2022 | D14: ="Q"&ROUNDUP(MONTH(B14)/3,0) -> Q1 | E14: =MONTH(B14) -> 1 | F14: =CHOOSE(E14,"Winter","Winter","Spring","Spring","Spring","Summer","Summer","Summer","Autumn","Autumn","Autumn","Winter") -> Winter | G14: =IF(F14="Winter",1,0) -> 1 | H14: 13 | I14: 5620 | J14: 89.4 | K14: 1420000 | L14: 104.9 | M14: 74.4 | N14: 1820 | O14: =K14/I14 -> 252.66904 | P14: =I14/N14 -> 3.0879121 | Q14: =IF(J14>85,1,0) -> 1 | R14: =M14-M13 -> 0.4
... A49: 2024-12 | B49: 45627 | C49: =YEAR(B49) -> 2024 | D49: ="Q"&ROUNDUP(MONTH(B49)/3,0) -> Q4 | E49: =MONTH(B49) -> 12 | F49: =CHOOSE(E49,"Winter","Winter","Spring","Spring","Spring","Summer","Summer","Summer","Autumn","Autumn","Autumn","Winter") -> Winter | G49: =IF(F49="Winter",1,0) -> 1 | H49: 48 | I49: 6340 | J49: 97.9 | K49: 1590000 | L49: 114.2 | M49: 90.2 | N49: 2160 | O49: =K49/I49 -> 250.78864 | P49: =I49/N49 -> 2.9351852 | Q49: =IF(J49>85,1,0) -> 1 | R49: =M49-M48 -> 0.3

Sheet Descriptive_Stats
A1: Unit 4 · Central tendency, dispersion and shape
A2: All values are live formulas on the Data sheet
A4: Statistic | B4: ER_Visits | C4: ICU_Util_Rate | D4: Pub_Health_Exp | E4: Pop_Density_Idx | F4: Vacc_Coverage | G4: Flu_Resp_Cases
A5: Count | B5: =COUNT(Data!$I$2:$I$49) -> 48 | C5: =COUNT(Data!$J$2:$J$49) -> 48 | D5: =COUNT(Data!$K$2:$K$49) -> 48 | E5: =COUNT(Data!$L$2:$L$49) -> 48 | F5: =COUNT(Data!$M$2:$M$49) -> 48 | G5: =COUNT(Data!$N$2:$N$49) -> 48
A6: Mean | B6: =AVERAGE(Data!$I$2:$I$49) -> 4745 | C6: =AVERAGE(Data!$J$2:$J$49) -> 75.920833 | D6: =AVERAGE(Data!$K$2:$K$49) -> 1249166.7 | E6: =AVERAGE(Data!$L$2:$L$49) -> 107.92708 | F6: =AVERAGE(Data!$M$2:$M$49) -> 79.652083 | G6: =AVERAGE(Data!$N$2:$N$49) -> 1253.125
A7: Median | B7: =MEDIAN(Data!$I$2:$I$49) -> 4585 | C7: =MEDIAN(Data!$J$2:$J$49) -> 74.35 | D7: =MEDIAN(Data!$K$2:$K$49) -> 1215000 | E7: =MEDIAN(Data!$L$2:$L$49) -> 107.75 | F7: =MEDIAN(Data!$M$2:$M$49) -> 79.85 | G7: =MEDIAN(Data!$N$2:$N$49) -> 1180
A8: Std Dev (sample) | B8: =_xlfn.STDEV.S(Data!$I$2:$I$49) -> 739.37869 | C8: =_xlfn.STDEV.S(Data!$J$2:$J$49) -> 10.468473 | D8: =_xlfn.STDEV.S(Data!$K$2:$K$49) -> 148163.7 | E8: =_xlfn.STDEV.S(Data!$L$2:$L$49) -> 3.5638695 | F8: =_xlfn.STDEV.S(Data!$M$2:$M$49) -> 7.2477726 | G8: =_xlfn.STDEV.S(Data!$N$2:$N$49) -> 417.38882
A9: Variance | B9: =VAR(Data!$I$2:$I$49) -> 546680.85 | C9: =VAR(Data!$J$2:$J$49) -> 109.58892 | D9: =VAR(Data!$K$2:$K$49) -> 2.1952482e+10 | E9: =VAR(Data!$L$2:$L$49) -> 12.701166 | F9: =VAR(Data!$M$2:$M$49) -> 52.530208 | G9: =VAR(Data!$N$2:$N$49) -> 174213.43
A10: Coefficient of variation % | B10: =B6/B7*100 -> 103.48964 | C10: =C6/C7*100 -> 102.11275 | D10: =D6/D7*100 -> 102.81207 | E10: =E6/E7*100 -> 100.16435 | F10: =F6/F7*100 -> 99.752139 | G10: =G6/G7*100 -> 106.19703
A11: Minimum | B11: =MIN(Data!$I$2:$I$49) -> 3580 | C11: =MIN(Data!$J$2:$J$49) -> 59.4 | D11: =MIN(Data!$K$2:$K$49) -> 1020000 | E11: =MIN(Data!$L$2:$L$49) -> 102.3 | F11: =MIN(Data!$M$2:$M$49) -> 61.2 | G11: =MIN(Data!$N$2:$N$49) -> 690
A12: Q1 (25th pct) | B12: =_xlfn.QUARTILE.INC(Data!$I$2:$I$49,1) -> 4170 | C12: =_xlfn.QUARTILE.INC(Data!$J$2:$J$49,1) -> 68.1 | D12: =_xlfn.QUARTILE.INC(Data!$K$2:$K$49,1) -> 1137500 | E12: =_xlfn.QUARTILE.INC(Data!$L$2:$L$49,1) -> 104.825 | F12: =_xlfn.QUARTILE.INC(Data!$M$2:$M$49,1) -> 74.3 | G12: =_xlfn.QUARTILE.INC(Data!$N$2:$N$49,1) -> 897.5
A13: Q3 (75th pct) | B13: =_xlfn.QUARTILE.INC(Data!$I$2:$I$49,3) -> 5287.5 | C13: =_xlfn.QUARTILE.INC(Data!$J$2:$J$49,3) -> 83.45 | D13: =_xlfn.QUARTILE.INC(Data!$K$2:$K$49,3) -> 1345000 | E13: =_xlfn.QUARTILE.INC(Data!$L$2:$L$49,3) -> 110.875 | F13: =_xlfn.QUARTILE.INC(Data!$M$2:$M$49,3) -> 85.225 | G13: =_xlfn.QUARTILE.INC(Data!$N$2:$N$49,3) -> 1562.5
A14: Maximum | B14: =MAX(Data!$I$2:$I$49) -> 6340 | C14: =MAX(Data!$J$2:$J$49) -> 97.9 | D14: =MAX(Data!$K$2:$K$49) -> 1590000 | E14: =MAX(Data!$L$2:$L$49) -> 114.2 | F14: =MAX(Data!$M$2:$M$49) -> 90.2 | G14: =MAX(Data!$N$2:$N$49) -> 2160
A15: Range | B15: =B14-B11 -> 2760 | C15: =C14-C11 -> 38.5 | D15: =D14-D11 -> 570000 | E15: =E14-E11 -> 11.9 | F15: =F14-F11 -> 29 | G15: =G14-G11 -> 1470
A16: Interquartile range (IQR) | B16: =B13-B12 -> 1117.5 | C16: =C13-C12 -> 15.35 | D16: =D13-D12 -> 207500 | E16: =E13-E12 -> 6.05 | F16: =F13-F12 -> 10.925 | G16: =G13-G12 -> 665
A17: Skewness | B17: =SKEW(Data!$I$2:$I$49) -> 0.47048281 | C17: =SKEW(Data!$J$2:$J$49) -> 0.4253656 | D17: =SKEW(Data!$K$2:$K$49) -> 0.60004766 | E17: =SKEW(Data!$L$2:$L$49) -> 0.12234181 | F17: =SKEW(Data!$M$2:$M$49) -> -0.51215267 | G17: =SKEW(Data!$N$2:$N$49) -> 0.60433285
A18: Excess kurtosis | B18: =KURT(Data!$I$2:$I$49) -> -0.69225832 | C18: =KURT(Data!$J$2:$J$49) -> -0.80351441 | D18: =KURT(Data!$K$2:$K$49) -> -0.47168095 | E18: =KURT(Data!$L$2:$L$49) -> -1.215888 | F18: =KURT(Data!$M$2:$M$49) -> -0.29038308 | G18: =KURT(Data!$N$2:$N$49) -> -0.76719637
A19: Std error of mean | B19: =B8/SQRT(B5) -> 106.72012 | C19: =C8/SQRT(C5) -> 1.5109939 | D19: =D8/SQRT(D5) -> 21385.588 | E19: =E8/SQRT(E5) -> 0.51440025 | F19: =F8/SQRT(F5) -> 1.0461259 | G19: =G8/SQRT(G5) -> 60.244888
A20: Lower fence (Q1-1.5×IQR) | B20: =B12-1.5*B16 -> 2493.75 | C20: =C12-1.5*C16 -> 45.075 | D20: =D12-1.5*D16 -> 826250 | E20: =E12-1.5*E16 -> 95.75 | F20: =F12-1.5*F16 -> 57.9125 | G20: =G12-1.5*G16 -> -100
A21: Upper fence (Q3+1.5×IQR) | B21: =B13+1.5*B16 -> 6963.75 | C21: =C13+1.5*C16 -> 106.475 | D21: =D13+1.5*D16 -> 1656250 | E21: =E13+1.5*E16 -> 119.95 | F21: =F13+1.5*F16 -> 101.6125 | G21: =G13+1.5*G16 -> 2560
A22: IQR outliers (count) | B22: =COUNTIF(Data!$I$2:$I$49,"<"&B20)+COUNTIF(Data!$I$2:$I$49,">"&B21) -> 0 | C22: =COUNTIF(Data!$J$2:$J$49,"<"&C20)+COUNTIF(Data!$J$2:$J$49,">"&C21) -> 0 | D22: =COUNTIF(Data!$K$2:$K$49,"<"&D20)+COUNTIF(Data!$K$2:$K$49,">"&D21) -> 0 | E22: =COUNTIF(Data!$L$2:$L$49,"<"&E20)+COUNTIF(Data!$L$2:$L$49,">"&E21) -> 0 | F22: =COUNTIF(Data!$M$2:$M$49,"<"&F20)+COUNTIF(Data!$M$2:$M$49,">"&F21) -> 0 | G22: =COUNTIF(Data!$N$2:$N$49,"<"&G20)+COUNTIF(Data!$N$2:$N$49,">"&G21) -> 0
A23: Mean − Median | B23: =B6-B7 -> 160 | C23: =C6-C7 -> 1.5708333 | D23: =D6-D7 -> 34166.667 | E23: =E6-E7 -> 0.17708333 | F23: =F6-F7 -> -0.19791667 | G23: =G6-G7 -> 73.125
A24: Shape interpretation | B24: =IF(ABS(B17)<0.5,"Approximately symmetric",IF(B17>0,"Moderately right-skewed","Moderately left-skewed"))&IF(B18<0,", platykurtic",", leptokurtic") -> Approximately symmetric, platykurtic | C24: =IF(ABS(C17)<0.5,"Approximately symmetric",IF(C17>0,"Moderately right-skewed","Moderately left-skewed"))&IF(C18<0,", platykurtic",", leptokurtic") -> Approximately symmetric, platykurtic | D24: =IF(ABS(D17)<0.5,"Approximately symmetric",IF(D17>0,"Moderately right-skewed","Moderately left-skewed"))&IF(D18<0,", platykurtic",", leptokurtic") -> Moderately right-skewed, platykurtic | E24: =IF(ABS(E17)<0.5,"Approximately symmetric",IF(E17>0,"Moderately right-skewed","Moderately left-skewed"))&IF(E18<0,", platykurtic",", leptokurtic") -> Approximately symmetric, platykurtic | F24: =IF(ABS(F17)<0.5,"Approximately symmetric",IF(F17>0,"Moderately right-skewed","Moderately left-skewed"))&IF(F18<0,", platykurtic",", leptokurtic") -> Moderately left-skewed, platykurtic | G24: =IF(ABS(G17)<0.5,"Approximately symmetric",IF(G17>0,"Moderately right-skewed","Moderately left-skewed"))&IF(G18<0,", platykurtic",", leptokurtic") -> Moderately right-skewed, platykurtic
A27: Normality (Shapiro-Wilk p, from notebook) | B27: 0.0842 | C27: 0.0763 | D27: 0.0437 | E27: 0.045 | F27: 0.1194 | G27: 0.0043
A29: Interpretation: all demand variables are right-skewed (mean > median) because of winter surges; no value breaches the 1.5×IQR fences, so extremes are seasonal peaks, not errors.

Sheet Frequency
A1: Unit 4 · Frequency distributions and histograms
A2: Bins are [lower, upper) — COUNTIFS formulas
A4: ER visits per month
A5: Lower | B5: Upper | C5: Bin | D5: Frequency | E5: Relative % | F5: Cumulative %
A6: 3500 | B6: =A6+250 -> 3750 | C6: =TEXT(A6,"#,##0")&"–"&TEXT(B6,"#,##0") -> 3,500–3,750 | D6: =COUNTIFS(Data!$I$2:$I$49,">="&A6,Data!$I$2:$I$49,"<"&B6) -> 3 | E6: =D6/SUM($D$6:$D$17)*100 -> 6.25 | F6: =E6 -> 6.25
A7: 3750 | B7: =A7+250 -> 4000 | C7: =TEXT(A7,"#,##0")&"–"&TEXT(B7,"#,##0") -> 3,750–4,000 | D7: =COUNTIFS(Data!$I$2:$I$49,">="&A7,Data!$I$2:$I$49,"<"&B7) -> 4 | E7: =D7/SUM($D$6:$D$17)*100 -> 8.3333333 | F7: =F6+E7 -> 14.583333
A8: 4000 | B8: =A8+250 -> 4250 | C8: =TEXT(A8,"#,##0")&"–"&TEXT(B8,"#,##0") -> 4,000–4,250 | D8: =COUNTIFS(Data!$I$2:$I$49,">="&A8,Data!$I$2:$I$49,"<"&B8) -> 8 | E8: =D8/SUM($D$6:$D$17)*100 -> 16.666667 | F8: =F7+E8 -> 31.25
A9: 4250 | B9: =A9+250 -> 4500 | C9: =TEXT(A9,"#,##0")&"–"&TEXT(B9,"#,##0") -> 4,250–4,500 | D9: =COUNTIFS(Data!$I$2:$I$49,">="&A9,Data!$I$2:$I$49,"<"&B9) -> 7 | E9: =D9/SUM($D$6:$D$17)*100 -> 14.583333 | F9: =F8+E9 -> 45.833333
A10: 4500 | B10: =A10+250 -> 4750 | C10: =TEXT(A10,"#,##0")&"–"&TEXT(B10,"#,##0") -> 4,500–4,750 | D10: =COUNTIFS(Data!$I$2:$I$49,">="&A10,Data!$I$2:$I$49,"<"&B10) -> 5 | E10: =D10/SUM($D$6:$D$17)*100 -> 10.416667 | F10: =F9+E10 -> 56.25
A11: 4750 | B11: =A11+250 -> 5000 | C11: =TEXT(A11,"#,##0")&"–"&TEXT(B11,"#,##0") -> 4,750–5,000 | D11: =COUNTIFS(Data!$I$2:$I$49,">="&A11,Data!$I$2:$I$49,"<"&B11) -> 5 | E11: =D11/SUM($D$6:$D$17)*100 -> 10.416667 | F11: =F10+E11 -> 66.666667
A12: 5000 | B12: =A12+250 -> 5250 | C12: =TEXT(A12,"#,##0")&"–"&TEXT(B12,"#,##0") -> 5,000–5,250 | D12: =COUNTIFS(Data!$I$2:$I$49,">="&A12,Data!$I$2:$I$49,"<"&B12) -> 3 | E12: =D12/SUM($D$6:$D$17)*100 -> 6.25 | F12: =F11+E12 -> 72.916667
A13: 5250 | B13: =A13+250 -> 5500 | C13: =TEXT(A13,"#,##0")&"–"&TEXT(B13,"#,##0") -> 5,250–5,500 | D13: =COUNTIFS(Data!$I$2:$I$49,">="&A13,Data!$I$2:$I$49,"<"&B13) -> 4 | E13: =D13/SUM($D$6:$D$17)*100 -> 8.3333333 | F13: =F12+E13 -> 81.25
A14: 5500 | B14: =A14+250 -> 5750 | C14: =TEXT(A14,"#,##0")&"–"&TEXT(B14,"#,##0") -> 5,500–5,750 | D14: =COUNTIFS(Data!$I$2:$I$49,">="&A14,Data!$I$2:$I$49,"<"&B14) -> 3 | E14: =D14/SUM($D$6:$D$17)*100 -> 6.25 | F14: =F13+E14 -> 87.5
A15: 5750 | B15: =A15+250 -> 6000 | C15: =TEXT(A15,"#,##0")&"–"&TEXT(B15,"#,##0") -> 5,750–6,000 | D15: =COUNTIFS(Data!$I$2:$I$49,">="&A15,Data!$I$2:$I$49,"<"&B15) -> 3 | E15: =D15/SUM($D$6:$D$17)*100 -> 6.25 | F15: =F14+E15 -> 93.75
A16: 6000 | B16: =A16+250 -> 6250 | C16: =TEXT(A16,"#,##0")&"–"&TEXT(B16,"#,##0") -> 6,000–6,250 | D16: =COUNTIFS(Data!$I$2:$I$49,">="&A16,Data!$I$2:$I$49,"<"&B16) -> 1 | E16: =D16/SUM($D$6:$D$17)*100 -> 2.0833333 | F16: =F15+E16 -> 95.833333
A17: 6250 | B17: =A17+250 -> 6500 | C17: =TEXT(A17,"#,##0")&"–"&TEXT(B17,"#,##0") -> 6,250–6,500 | D17: =COUNTIFS(Data!$I$2:$I$49,">="&A17,Data!$I$2:$I$49,"<"&B17) -> 2 | E17: =D17/SUM($D$6:$D$17)*100 -> 4.1666667 | F17: =F16+E17 -> 100
C18: Total | D18: =SUM(D6:D17) -> 48
A21: ICU utilisation %
A22: Lower | B22: Upper | C22: Bin | D22: Frequency | E22: Relative % | F22: Cumulative %
A23: 55 | B23: =A23+5 -> 60 | C23: =TEXT(A23,"0")&"–"&TEXT(B23,"0") -> 55–60 | D23: =COUNTIFS(Data!$J$2:$J$49,">="&A23,Data!$J$2:$J$49,"<"&B23) -> 1 | E23: =D23/SUM($D$23:$D$31)*100 -> 2.0833333 | F23: =E23 -> 2.0833333
A24: 60 | B24: =A24+5 -> 65 | C24: =TEXT(A24,"0")&"–"&TEXT(B24,"0") -> 60–65 | D24: =COUNTIFS(Data!$J$2:$J$49,">="&A24,Data!$J$2:$J$49,"<"&B24) -> 6 | E24: =D24/SUM($D$23:$D$31)*100 -> 12.5 | F24: =F23+E24 -> 14.583333
A25: 65 | B25: =A25+5 -> 70 | C25: =TEXT(A25,"0")&"–"&TEXT(B25,"0") -> 65–70 | D25: =COUNTIFS(Data!$J$2:$J$49,">="&A25,Data!$J$2:$J$49,"<"&B25) -> 11 | E25: =D25/SUM($D$23:$D$31)*100 -> 22.916667 | F25: =F24+E25 -> 37.5
A26: 70 | B26: =A26+5 -> 75 | C26: =TEXT(A26,"0")&"–"&TEXT(B26,"0") -> 70–75 | D26: =COUNTIFS(Data!$J$2:$J$49,">="&A26,Data!$J$2:$J$49,"<"&B26) -> 9 | E26: =D26/SUM($D$23:$D$31)*100 -> 18.75 | F26: =F25+E26 -> 56.25
A27: 75 | B27: =A27+5 -> 80 | C27: =TEXT(A27,"0")&"–"&TEXT(B27,"0") -> 75–80 | D27: =COUNTIFS(Data!$J$2:$J$49,">="&A27,Data!$J$2:$J$49,"<"&B27) -> 5 | E27: =D27/SUM($D$23:$D$31)*100 -> 10.416667 | F27: =F26+E27 -> 66.666667
A28: 80 | B28: =A28+5 -> 85 | C28: =TEXT(A28,"0")&"–"&TEXT(B28,"0") -> 80–85 | D28: =COUNTIFS(Data!$J$2:$J$49,">="&A28,Data!$J$2:$J$49,"<"&B28) -> 5 | E28: =D28/SUM($D$23:$D$31)*100 -> 10.416667 | F28: =F27+E28 -> 77.083333
A29: 85 | B29: =A29+5 -> 90 | C29: =TEXT(A29,"0")&"–"&TEXT(B29,"0") -> 85–90 | D29: =COUNTIFS(Data!$J$2:$J$49,">="&A29,Data!$J$2:$J$49,"<"&B29) -> 4 | E29: =D29/SUM($D$23:$D$31)*100 -> 8.3333333 | F29: =F28+E29 -> 85.416667
A30: 90 | B30: =A30+5 -> 95 | C30: =TEXT(A30,"0")&"–"&TEXT(B30,"0") -> 90–95 | D30: =COUNTIFS(Data!$J$2:$J$49,">="&A30,Data!$J$2:$J$49,"<"&B30) -> 5 | E30: =D30/SUM($D$23:$D$31)*100 -> 10.416667 | F30: =F29+E30 -> 95.833333
A31: 95 | B31: =A31+5 -> 100 | C31: =TEXT(A31,"0")&"–"&TEXT(B31,"0") -> 95–100 | D31: =COUNTIFS(Data!$J$2:$J$49,">="&A31,Data!$J$2:$J$49,"<"&B31) -> 2 | E31: =D31/SUM($D$23:$D$31)*100 -> 4.1666667 | F31: =F30+E31 -> 100
C32: Total | D32: =SUM(D23:D31) -> 48
A35: Flu / respiratory cases
A36: Lower | B36: Upper | C36: Bin | D36: Frequency | E36: Relative % | F36: Cumulative %
A37: 600 | B37: =A37+200 -> 800 | C37: =TEXT(A37,"#,##0")&"–"&TEXT(B37,"#,##0") -> 600–800 | D37: =COUNTIFS(Data!$N$2:$N$49,">="&A37,Data!$N$2:$N$49,"<"&B37) -> 4 | E37: =D37/SUM($D$37:$D$44)*100 -> 8.3333333 | F37: =E37 -> 8.3333333
A38: 800 | B38: =A38+200 -> 1000 | C38: =TEXT(A38,"#,##0")&"–"&TEXT(B38,"#,##0") -> 800–1,000 | D38: =COUNTIFS(Data!$N$2:$N$49,">="&A38,Data!$N$2:$N$49,"<"&B38) -> 14 | E38: =D38/SUM($D$37:$D$44)*100 -> 29.166667 | F38: =F37+E38 -> 37.5
A39: 1000 | B39: =A39+200 -> 1200 | C39: =TEXT(A39,"#,##0")&"–"&TEXT(B39,"#,##0") -> 1,000–1,200 | D39: =COUNTIFS(Data!$N$2:$N$49,">="&A39,Data!$N$2:$N$49,"<"&B39) -> 8 | E39: =D39/SUM($D$37:$D$44)*100 -> 16.666667 | F39: =F38+E39 -> 54.166667
A40: 1200 | B40: =A40+200 -> 1400 | C40: =TEXT(A40,"#,##0")&"–"&TEXT(B40,"#,##0") -> 1,200–1,400 | D40: =COUNTIFS(Data!$N$2:$N$49,">="&A40,Data!$N$2:$N$49,"<"&B40) -> 6 | E40: =D40/SUM($D$37:$D$44)*100 -> 12.5 | F40: =F39+E40 -> 66.666667
A41: 1400 | B41: =A41+200 -> 1600 | C41: =TEXT(A41,"#,##0")&"–"&TEXT(B41,"#,##0") -> 1,400–1,600 | D41: =COUNTIFS(Data!$N$2:$N$49,">="&A41,Data!$N$2:$N$49,"<"&B41) -> 5 | E41: =D41/SUM($D$37:$D$44)*100 -> 10.416667 | F41: =F40+E41 -> 77.083333
A42: 1600 | B42: =A42+200 -> 1800 | C42: =TEXT(A42,"#,##0")&"–"&TEXT(B42,"#,##0") -> 1,600–1,800 | D42: =COUNTIFS(Data!$N$2:$N$49,">="&A42,Data!$N$2:$N$49,"<"&B42) -> 3 | E42: =D42/SUM($D$37:$D$44)*100 -> 6.25 | F42: =F41+E42 -> 83.333333
A43: 1800 | B43: =A43+200 -> 2000 | C43: =TEXT(A43,"#,##0")&"–"&TEXT(B43,"#,##0") -> 1,800–2,000 | D43: =COUNTIFS(Data!$N$2:$N$49,">="&A43,Data!$N$2:$N$49,"<"&B43) -> 6 | E43: =D43/SUM($D$37:$D$44)*100 -> 12.5 | F43: =F42+E43 -> 95.833333
A44: 2000 | B44: =A44+200 -> 2200 | C44: =TEXT(A44,"#,##0")&"–"&TEXT(B44,"#,##0") -> 2,000–2,200 | D44: =COUNTIFS(Data!$N$2:$N$49,">="&A44,Data!$N$2:$N$49,"<"&B44) -> 2 | E44: =D44/SUM($D$37:$D$44)*100 -> 4.1666667 | F44: =F43+E44 -> 100
C45: Total | D45: =SUM(D37:D44) -> 48

Sheet Pivot_Tables
A1: Unit 4 · Native PivotTables (source: Data!A1:R49)
A2: Right-click any table ▸ Refresh to update. Value-display modes: Sum, % of column total, % difference from previous year, Average.
A4: PT1. Sum of ER visits — Quarter × Year | H4: PT2. ER visits as % of column (annual) total | O4: PT3. ER visits — % difference from previous year (YoY)
A5: Sum - ER_Visits | B5: Year | H5: Sum - ER_Visits | I5: Year | O5: Sum - ER_Visits | P5: Year
A6: Quarter | B6: 2021 | C6: 2022 | D6: 2023 | E6: 2024 | F6: Total Result | H6: Quarter | I6: 2021 | J6: 2022 | K6: 2023 | L6: 2024 | M6: Total Result | O6: Quarter | P6: 2021 | Q6: 2022 | R6: 2023 | S6: 2024 | T6: Total Result
A7: Q1 | B7: 13510 | C7: 15410 | D7: 16360 | E7: 17240 | F7: 62520 | H7: Q1 | I7: 0.26500588 | J7: 0.27646215 | K7: 0.27747626 | L7: 0.27770619 | M7: 0.27449947 | O7: Q1 | Q7: 0.14063657 | R7: 0.06164828 | S7: 0.053789731
A8: Q2 | B8: 11210 | C8: 12100 | D8: 12770 | E8: 13430 | F8: 49510 | H8: Q2 | I8: 0.21989015 | J8: 0.2170793 | K8: 0.21658752 | L8: 0.21633376 | M8: 0.21737794 | O8: Q2 | Q8: 0.079393399 | R8: 0.055371901 | S8: 0.051683634
A9: Q3 | B9: 11530 | C9: 12430 | D9: 13160 | E9: 13860 | F9: 50980 | H9: Q3 | I9: 0.22616712 | J9: 0.22299964 | K9: 0.22320217 | L9: 0.22326031 | M9: 0.2238321 | O9: Q3 | Q9: 0.078057242 | R9: 0.058728882 | S9: 0.053191489
A10: Q4 | B10: 14730 | C10: 15800 | D10: 16670 | E10: 17550 | F10: 64750 | H10: Q4 | I10: 0.28893684 | J10: 0.28345892 | K10: 0.28273406 | L10: 0.28269974 | M10: 0.28429048 | O10: Q4 | Q10: 0.072640869 | R10: 0.055063291 | S10: 0.052789442
A11: Total Result | B11: 50980 | C11: 55740 | D11: 58960 | E11: 62080 | F11: 227760 | H11: Total Result | I11: 1 | J11: 1 | K11: 1 | L11: 1 | M11: 1 | O11: Total Result | Q11: 0.093369949 | R11: 0.05776821 | S11: 0.052917232
A17: PT4. Average ICU utilisation % — Season × Year | H17: PT5. Annual KPI pivot (sums)
A18: Average - ICU_Util_Rate | B18: Year | H18: Year | I18: Data
A19: Season | B19: 2021 | C19: 2022 | D19: 2023 | E19: 2024 | F19: Total Result | H19: 2021 | I19: Sum - ER_Visits | J19: 50980
A20: Autumn | B20: 73.966667 | C20: 77.266667 | D20: 80.666667 | E20: 83.933333 | F20: 78.958333 | I20: Sum - Pub_Health_Exp | J20: 13760000
A21: Spring | B21: 65.166667 | C21: 69.633333 | D21: 72.8 | E21: 75.8 | F21: 70.85 | I21: Sum - Flu_Resp_Cases | J21: 12590
A22: Summer | B22: 61.066667 | C22: 64.1 | D22: 67.133333 | E22: 69.933333 | F22: 65.558333 | I22: Sum - ICU_Over_85 | J22: 1
A23: Winter | B23: 79.566667 | C23: 87.2 | D23: 91.3 | E23: 95.2 | F23: 88.316667 | H23: 2022 | I23: Sum - ER_Visits | J23: 55740
A24: Total Result | B24: 69.941667 | C24: 74.55 | D24: 77.975 | E24: 81.216667 | F24: 75.920833 | I24: Sum - Pub_Health_Exp | J24: 14690000
I25: Sum - Flu_Resp_Cases | J25: 14630
I26: Sum - ICU_Over_85 | J26: 2
H27: 2023 | I27: Sum - ER_Visits | J27: 58960
I28: Sum - Pub_Health_Exp | J28: 15390000
I29: Sum - Flu_Resp_Cases | J29: 15820
A30: PT6. Average ICU utilisation % — Month × Year | H30: PT7. Average $ per ER visit and flu cases — Season | I30: Sum - ICU_Over_85 | J30: 4
A31: Average - ICU_Util_Rate | B31: Year | H31: Season | I31: Data
A32: MonthNum | B32: 2021 | C32: 2022 | D32: 2023 | E32: 2024 | F32: Total Result | H32: Autumn | I32: Average - Exp_per_ER_Visit | J32: 259.83022
A33: 1 | B33: 78.4 | C33: 89.4 | D33: 93.2 | E33: 97.3 | F33: 89.575 | I33: Average - Flu_Resp_Cases | J33: 1387.5
A34: 2 | B34: 74.1 | C34: 82.1 | D34: 86.7 | E34: 90.4 | F34: 83.325 | I34: Average - ER_Visits | J34: 4960
A35: 3 | B35: 69.5 | C35: 74.8 | D35: 78.4 | E35: 81.7 | F35: 76.1 | H35: Spring | I35: Average - Exp_per_ER_Visit | J35: 268.62229
A36: 4 | B36: 64.2 | C36: 68.9 | D36: 71.9 | E36: 74.8 | F36: 69.95 | I36: Average - Flu_Resp_Cases | J36: 1006.6667
A37: 5 | B37: 61.8 | C37: 65.2 | D37: 68.1 | E37: 70.9 | F37: 66.5 | I37: Average - ER_Visits | J37: 4377.5
A38: 6 | B38: 59.4 | C38: 62.4 | D38: 65.4 | E38: 68.1 | F38: 63.825 | H38: Summer | I38: Average - Exp_per_ER_Visit | J38: 276.46924
A39: 7 | B39: 60.1 | C39: 63.1 | D39: 66.2 | E39: 69 | F39: 64.6 | I39: Average - Flu_Resp_Cases | J39: 851.66667
A40: 8 | B40: 63.7 | C40: 66.8 | D40: 69.8 | E40: 72.7 | F40: 68.25 | I40: Average - ER_Visits | J40: 4050.8333
A41: 9 | B41: 68.9 | C41: 71.5 | D41: 74.6 | E41: 77.6 | F41: 73.15 | H41: Winter | I41: Average - Exp_per_ER_Visit | J41: 254.12161
A42: 10 | B42: 73.2 | C42: 76.9 | D42: 80.3 | E42: 83.6 | F42: 78.5 | I42: Average - Flu_Resp_Cases | J42: 1766.6667
A43: 11 | B43: 79.8 | C43: 83.4 | D43: 87.1 | E43: 90.6 | F43: 85.225 | I43: Average - ER_Visits | J43: 5591.6667
A44: 12 | B44: 86.2 | C44: 90.1 | D44: 94 | E44: 97.9 | F44: 92.05 | H44: Total Average - Exp_per_ER_Visit | J44: 264.76084
A45: Total Result | B45: 69.941667 | C45: 74.55 | D45: 77.975 | E45: 81.216667 | F45: 75.920833 | H45: Total Average - Flu_Resp_Cases | J45: 1253.125
H46: Total Average - ER_Visits | J46: 4745

Sheet Pivot_Formulas
A1: Unit 4 · Cross-tabulations with calculated fields, % of column total and YoY growth
A2: SUMIFS / AVERAGEIFS / COUNTIFS on the Data sheet (native PivotTables are on the Pivot_Tables sheet)
A4: Table 1. ER visits — Quarter × Year (sum) | H4: Table 2. % of column (annual) total | O4: Table 3. Year-over-Year growth %
A5: Quarter | B5: 2021 | C5: 2022 | D5: 2023 | E5: 2024 | F5: Total | H5: Quarter | I5: 2021 | J5: 2022 | K5: 2023 | L5: 2024 | M5: All years | O5: Quarter | P5: 2022 vs 21 | Q5: 2023 vs 22 | R5: 2024 vs 23 | S5: CAGR 21–24
A6: Q1 | B6: =SUMIFS(Data!$I$2:$I$49,Data!$D$2:$D$49,$A6,Data!$C$2:$C$49,B$5) -> 13510 | C6: =SUMIFS(Data!$I$2:$I$49,Data!$D$2:$D$49,$A6,Data!$C$2:$C$49,C$5) -> 15410 | D6: =SUMIFS(Data!$I$2:$I$49,Data!$D$2:$D$49,$A6,Data!$C$2:$C$49,D$5) -> 16360 | E6: =SUMIFS(Data!$I$2:$I$49,Data!$D$2:$D$49,$A6,Data!$C$2:$C$49,E$5) -> 17240 | F6: =SUM(B6:E6) -> 62520 | H6: Q1 | I6: =B6/B$10 -> 0.26500588 | J6: =C6/C$10 -> 0.27646215 | K6: =D6/D$10 -> 0.27747626 | L6: =E6/E$10 -> 0.27770619 | M6: =F6/F$10 -> 0.27449947 | O6: Q1 | P6: =C6/B6-1 -> 0.14063657 | Q6: =D6/C6-1 -> 0.06164828 | R6: =E6/D6-1 -> 0.053789731 | S6: =(E6/B6)^(1/3)-1 -> 0.084660865
A7: Q2 | B7: =SUMIFS(Data!$I$2:$I$49,Data!$D$2:$D$49,$A7,Data!$C$2:$C$49,B$5) -> 11210 | C7: =SUMIFS(Data!$I$2:$I$49,Data!$D$2:$D$49,$A7,Data!$C$2:$C$49,C$5) -> 12100 | D7: =SUMIFS(Data!$I$2:$I$49,Data!$D$2:$D$49,$A7,Data!$C$2:$C$49,D$5) -> 12770 | E7: =SUMIFS(Data!$I$2:$I$49,Data!$D$2:$D$49,$A7,Data!$C$2:$C$49,E$5) -> 13430 | F7: =SUM(B7:E7) -> 49510 | H7: Q2 | I7: =B7/B$10 -> 0.21989015 | J7: =C7/C$10 -> 0.2170793 | K7: =D7/D$10 -> 0.21658752 | L7: =E7/E$10 -> 0.21633376 | M7: =F7/F$10 -> 0.21737794 | O7: Q2 | P7: =C7/B7-1 -> 0.079393399 | Q7: =D7/C7-1 -> 0.055371901 | R7: =E7/D7-1 -> 0.051683634 | S7: =(E7/B7)^(1/3)-1 -> 0.062078947
A8: Q3 | B8: =SUMIFS(Data!$I$2:$I$49,Data!$D$2:$D$49,$A8,Data!$C$2:$C$49,B$5) -> 11530 | C8: =SUMIFS(Data!$I$2:$I$49,Data!$D$2:$D$49,$A8,Data!$C$2:$C$49,C$5) -> 12430 | D8: =SUMIFS(Data!$I$2:$I$49,Data!$D$2:$D$49,$A8,Data!$C$2:$C$49,D$5) -> 13160 | E8: =SUMIFS(Data!$I$2:$I$49,Data!$D$2:$D$49,$A8,Data!$C$2:$C$49,E$5) -> 13860 | F8: =SUM(B8:E8) -> 50980 | H8: Q3 | I8: =B8/B$10 -> 0.22616712 | J8: =C8/C$10 -> 0.22299964 | K8: =D8/D$10 -> 0.22320217 | L8: =E8/E$10 -> 0.22326031 | M8: =F8/F$10 -> 0.2238321 | O8: Q3 | P8: =C8/B8-1 -> 0.078057242 | Q8: =D8/C8-1 -> 0.058728882 | R8: =E8/D8-1 -> 0.053191489 | S8: =(E8/B8)^(1/3)-1 -> 0.063272645
A9: Q4 | B9: =SUMIFS(Data!$I$2:$I$49,Data!$D$2:$D$49,$A9,Data!$C$2:$C$49,B$5) -> 14730 | C9: =SUMIFS(Data!$I$2:$I$49,Data!$D$2:$D$49,$A9,Data!$C$2:$C$49,C$5) -> 15800 | D9: =SUMIFS(Data!$I$2:$I$49,Data!$D$2:$D$49,$A9,Data!$C$2:$C$49,D$5) -> 16670 | E9: =SUMIFS(Data!$I$2:$I$49,Data!$D$2:$D$49,$A9,Data!$C$2:$C$49,E$5) -> 17550 | F9: =SUM(B9:E9) -> 64750 | H9: Q4 | I9: =B9/B$10 -> 0.28893684 | J9: =C9/C$10 -> 0.28345892 | K9: =D9/D$10 -> 0.28273406 | L9: =E9/E$10 -> 0.28269974 | M9: =F9/F$10 -> 0.28429048 | O9: Q4 | P9: =C9/B9-1 -> 0.072640869 | Q9: =D9/C9-1 -> 0.055063291 | R9: =E9/D9-1 -> 0.052789442 | S9: =(E9/B9)^(1/3)-1 -> 0.060127559
A10: Total | B10: =SUM(B6:B9) -> 50980 | C10: =SUM(C6:C9) -> 55740 | D10: =SUM(D6:D9) -> 58960 | E10: =SUM(E6:E9) -> 62080 | F10: =SUM(F6:F9) -> 227760 | O10: Total | P10: =C10/B10-1 -> 0.093369949 | Q10: =D10/C10-1 -> 0.05776821 | R10: =E10/D10-1 -> 0.052917232 | S10: =(E10/B10)^(1/3)-1 -> 0.067867311
A13: Table 4. Annual KPI pivot with calculated fields
A14: Year | B14: ER visits | C14: Flu cases | D14: Expenditure $ | E14: Mean ICU % | F14: Peak ICU % | G14: Months ICU>85% | H14: Mean vacc % | I14: Mean pop idx | J14: $ per ER visit | K14: ER visits per flu case | L14: YoY ER % | M14: YoY Exp % | N14: YoY $/visit %
A15: 2021 | B15: =SUMIFS(Data!$I$2:$I$49,Data!$C$2:$C$49,A15) -> 50980 | C15: =SUMIFS(Data!$N$2:$N$49,Data!$C$2:$C$49,A15) -> 12590 | D15: =SUMIFS(Data!$K$2:$K$49,Data!$C$2:$C$49,A15) -> 13760000 | E15: =AVERAGEIFS(Data!$J$2:$J$49,Data!$C$2:$C$49,A15) -> 69.941667 | F15: =SUMPRODUCT(MAX((Data!$C$2:$C$49=A15)*Data!$J$2:$J$49)) -> 86.2 | G15: =COUNTIFS(Data!$C$2:$C$49,A15,Data!$J$2:$J$49,">85") -> 1 | H15: =AVERAGEIFS(Data!$M$2:$M$49,Data!$C$2:$C$49,A15) -> 70.016667 | I15: =AVERAGEIFS(Data!$L$2:$L$49,Data!$C$2:$C$49,A15) -> 103.48333 | J15: =D15/B15 -> 269.90977 | K15: =B15/C15 -> 4.0492454
A16: 2022 | B16: =SUMIFS(Data!$I$2:$I$49,Data!$C$2:$C$49,A16) -> 55740 | C16: =SUMIFS(Data!$N$2:$N$49,Data!$C$2:$C$49,A16) -> 14630 | D16: =SUMIFS(Data!$K$2:$K$49,Data!$C$2:$C$49,A16) -> 14690000 | E16: =AVERAGEIFS(Data!$J$2:$J$49,Data!$C$2:$C$49,A16) -> 74.55 | F16: =SUMPRODUCT(MAX((Data!$C$2:$C$49=A16)*Data!$J$2:$J$49)) -> 90.1 | G16: =COUNTIFS(Data!$C$2:$C$49,A16,Data!$J$2:$J$49,">85") -> 2 | H16: =AVERAGEIFS(Data!$M$2:$M$49,Data!$C$2:$C$49,A16) -> 77.416667 | I16: =AVERAGEIFS(Data!$L$2:$L$49,Data!$C$2:$C$49,A16) -> 106.25 | J16: =D16/B16 -> 263.54503 | K16: =B16/C16 -> 3.8099795 | L16: =B16/B15-1 -> 0.093369949 | M16: =D16/D15-1 -> 0.067587209 | N16: =J16/J15-1 -> -0.023580984
A17: 2023 | B17: =SUMIFS(Data!$I$2:$I$49,Data!$C$2:$C$49,A17) -> 58960 | C17: =SUMIFS(Data!$N$2:$N$49,Data!$C$2:$C$49,A17) -> 15820 | D17: =SUMIFS(Data!$K$2:$K$49,Data!$C$2:$C$49,A17) -> 15390000 | E17: =AVERAGEIFS(Data!$J$2:$J$49,Data!$C$2:$C$49,A17) -> 77.975 | F17: =SUMPRODUCT(MAX((Data!$C$2:$C$49=A17)*Data!$J$2:$J$49)) -> 94 | G17: =COUNTIFS(Data!$C$2:$C$49,A17,Data!$J$2:$J$49,">85") -> 4 | H17: =AVERAGEIFS(Data!$M$2:$M$49,Data!$C$2:$C$49,A17) -> 82.966667 | I17: =AVERAGEIFS(Data!$L$2:$L$49,Data!$C$2:$C$49,A17) -> 109.34167 | J17: =D17/B17 -> 261.02442 | K17: =B17/C17 -> 3.7269279 | L17: =B17/B16-1 -> 0.05776821 | M17: =D17/D16-1 -> 0.047651464 | N17: =J17/J16-1 -> -0.0095642371
A18: 2024 | B18: =SUMIFS(Data!$I$2:$I$49,Data!$C$2:$C$49,A18) -> 62080 | C18: =SUMIFS(Data!$N$2:$N$49,Data!$C$2:$C$49,A18) -> 17110 | D18: =SUMIFS(Data!$K$2:$K$49,Data!$C$2:$C$49,A18) -> 16120000 | E18: =AVERAGEIFS(Data!$J$2:$J$49,Data!$C$2:$C$49,A18) -> 81.216667 | F18: =SUMPRODUCT(MAX((Data!$C$2:$C$49=A18)*Data!$J$2:$J$49)) -> 97.9 | G18: =COUNTIFS(Data!$C$2:$C$49,A18,Data!$J$2:$J$49,">85") -> 4 | H18: =AVERAGEIFS(Data!$M$2:$M$49,Data!$C$2:$C$49,A18) -> 88.208333 | I18: =AVERAGEIFS(Data!$L$2:$L$49,Data!$C$2:$C$49,A18) -> 112.63333 | J18: =D18/B18 -> 259.66495 | K18: =B18/C18 -> 3.6282876 | L18: =B18/B17-1 -> 0.052917232 | M18: =D18/D17-1 -> 0.047433398 | N18: =J18/J17-1 -> -0.0052082287
A21: Table 5. Mean ICU utilisation % — Season × Year | H21: Table 6. Seasonal share of annual ER visits (% of column total)
A22: Season | B22: 2021 | C22: 2022 | D22: 2023 | E22: 2024 | F22: Change 21→24 (pp) | H22: Season | I22: 2021 | J22: 2022 | K22: 2023 | L22: 2024
A23: Winter | B23: =AVERAGEIFS(Data!$J$2:$J$49,Data!$F$2:$F$49,$A23,Data!$C$2:$C$49,B$22) -> 79.566667 | C23: =AVERAGEIFS(Data!$J$2:$J$49,Data!$F$2:$F$49,$A23,Data!$C$2:$C$49,C$22) -> 87.2 | D23: =AVERAGEIFS(Data!$J$2:$J$49,Data!$F$2:$F$49,$A23,Data!$C$2:$C$49,D$22) -> 91.3 | E23: =AVERAGEIFS(Data!$J$2:$J$49,Data!$F$2:$F$49,$A23,Data!$C$2:$C$49,E$22) -> 95.2 | F23: =E23-B23 -> 15.633333 | H23: Winter | I23: =SUMIFS(Data!$I$2:$I$49,Data!$F$2:$F$49,$H23,Data!$C$2:$C$49,I$22)/SUMIFS(Data!$I$2:$I$49,Data!$C$2:$C$49,I$22) -> 0.28775991 | J23: =SUMIFS(Data!$I$2:$I$49,Data!$F$2:$F$49,$H23,Data!$C$2:$C$49,J$22)/SUMIFS(Data!$I$2:$I$49,Data!$C$2:$C$49,J$22) -> 0.29619663 | K23: =SUMIFS(Data!$I$2:$I$49,Data!$F$2:$F$49,$H23,Data!$C$2:$C$49,K$22)/SUMIFS(Data!$I$2:$I$49,Data!$C$2:$C$49,K$22) -> 0.29664179 | L23: =SUMIFS(Data!$I$2:$I$49,Data!$F$2:$F$49,$H23,Data!$C$2:$C$49,L$22)/SUMIFS(Data!$I$2:$I$49,Data!$C$2:$C$49,L$22) -> 0.296875
A24: Spring | B24: =AVERAGEIFS(Data!$J$2:$J$49,Data!$F$2:$F$49,$A24,Data!$C$2:$C$49,B$22) -> 65.166667 | C24: =AVERAGEIFS(Data!$J$2:$J$49,Data!$F$2:$F$49,$A24,Data!$C$2:$C$49,C$22) -> 69.633333 | D24: =AVERAGEIFS(Data!$J$2:$J$49,Data!$F$2:$F$49,$A24,Data!$C$2:$C$49,D$22) -> 72.8 | E24: =AVERAGEIFS(Data!$J$2:$J$49,Data!$F$2:$F$49,$A24,Data!$C$2:$C$49,E$22) -> 75.8 | F24: =E24-B24 -> 10.633333 | H24: Spring | I24: =SUMIFS(Data!$I$2:$I$49,Data!$F$2:$F$49,$H24,Data!$C$2:$C$49,I$22)/SUMIFS(Data!$I$2:$I$49,Data!$C$2:$C$49,I$22) -> 0.23165947 | J24: =SUMIFS(Data!$I$2:$I$49,Data!$F$2:$F$49,$H24,Data!$C$2:$C$49,J$22)/SUMIFS(Data!$I$2:$I$49,Data!$C$2:$C$49,J$22) -> 0.23053463 | K24: =SUMIFS(Data!$I$2:$I$49,Data!$F$2:$F$49,$H24,Data!$C$2:$C$49,K$22)/SUMIFS(Data!$I$2:$I$49,Data!$C$2:$C$49,K$22) -> 0.23032564 | L24: =SUMIFS(Data!$I$2:$I$49,Data!$F$2:$F$49,$H24,Data!$C$2:$C$49,L$22)/SUMIFS(Data!$I$2:$I$49,Data!$C$2:$C$49,L$22) -> 0.23018686
A25: Summer | B25: =AVERAGEIFS(Data!$J$2:$J$49,Data!$F$2:$F$49,$A25,Data!$C$2:$C$49,B$22) -> 61.066667 | C25: =AVERAGEIFS(Data!$J$2:$J$49,Data!$F$2:$F$49,$A25,Data!$C$2:$C$49,C$22) -> 64.1 | D25: =AVERAGEIFS(Data!$J$2:$J$49,Data!$F$2:$F$49,$A25,Data!$C$2:$C$49,D$22) -> 67.133333 | E25: =AVERAGEIFS(Data!$J$2:$J$49,Data!$F$2:$F$49,$A25,Data!$C$2:$C$49,E$22) -> 69.933333 | F25: =E25-B25 -> 8.8666667 | H25: Summer | I25: =SUMIFS(Data!$I$2:$I$49,Data!$F$2:$F$49,$H25,Data!$C$2:$C$49,I$22)/SUMIFS(Data!$I$2:$I$49,Data!$C$2:$C$49,I$22) -> 0.21557474 | J25: =SUMIFS(Data!$I$2:$I$49,Data!$F$2:$F$49,$H25,Data!$C$2:$C$49,J$22)/SUMIFS(Data!$I$2:$I$49,Data!$C$2:$C$49,J$22) -> 0.21277359 | K25: =SUMIFS(Data!$I$2:$I$49,Data!$F$2:$F$49,$H25,Data!$C$2:$C$49,K$22)/SUMIFS(Data!$I$2:$I$49,Data!$C$2:$C$49,K$22) -> 0.21285617 | L25: =SUMIFS(Data!$I$2:$I$49,Data!$F$2:$F$49,$H25,Data!$C$2:$C$49,L$22)/SUMIFS(Data!$I$2:$I$49,Data!$C$2:$C$49,L$22) -> 0.21278995
A26: Autumn | B26: =AVERAGEIFS(Data!$J$2:$J$49,Data!$F$2:$F$49,$A26,Data!$C$2:$C$49,B$22) -> 73.966667 | C26: =AVERAGEIFS(Data!$J$2:$J$49,Data!$F$2:$F$49,$A26,Data!$C$2:$C$49,C$22) -> 77.266667 | D26: =AVERAGEIFS(Data!$J$2:$J$49,Data!$F$2:$F$49,$A26,Data!$C$2:$C$49,D$22) -> 80.666667 | E26: =AVERAGEIFS(Data!$J$2:$J$49,Data!$F$2:$F$49,$A26,Data!$C$2:$C$49,E$22) -> 83.933333 | F26: =E26-B26 -> 9.9666667 | H26: Autumn | I26: =SUMIFS(Data!$I$2:$I$49,Data!$F$2:$F$49,$H26,Data!$C$2:$C$49,I$22)/SUMIFS(Data!$I$2:$I$49,Data!$C$2:$C$49,I$22) -> 0.26500588 | J26: =SUMIFS(Data!$I$2:$I$49,Data!$F$2:$F$49,$H26,Data!$C$2:$C$49,J$22)/SUMIFS(Data!$I$2:$I$49,Data!$C$2:$C$49,J$22) -> 0.26049516 | K26: =SUMIFS(Data!$I$2:$I$49,Data!$F$2:$F$49,$H26,Data!$C$2:$C$49,K$22)/SUMIFS(Data!$I$2:$I$49,Data!$C$2:$C$49,K$22) -> 0.26017639 | L26: =SUMIFS(Data!$I$2:$I$49,Data!$F$2:$F$49,$H26,Data!$C$2:$C$49,L$22)/SUMIFS(Data!$I$2:$I$49,Data!$C$2:$C$49,L$22) -> 0.2601482
A29: Table 7. ICU utilisation % — Month × Year (red = above 85% safe-occupancy threshold)
A30: Month | B30: 2021 | C30: 2022 | D30: 2023 | E30: 2024
A31: 1 | B31: =AVERAGEIFS(Data!$J$2:$J$49,Data!$E$2:$E$49,$A31,Data!$C$2:$C$49,B$30) -> 78.4 | C31: =AVERAGEIFS(Data!$J$2:$J$49,Data!$E$2:$E$49,$A31,Data!$C$2:$C$49,C$30) -> 89.4 | D31: =AVERAGEIFS(Data!$J$2:$J$49,Data!$E$2:$E$49,$A31,Data!$C$2:$C$49,D$30) -> 93.2 | E31: =AVERAGEIFS(Data!$J$2:$J$49,Data!$E$2:$E$49,$A31,Data!$C$2:$C$49,E$30) -> 97.3
A32: 2 | B32: =AVERAGEIFS(Data!$J$2:$J$49,Data!$E$2:$E$49,$A32,Data!$C$2:$C$49,B$30) -> 74.1 | C32: =AVERAGEIFS(Data!$J$2:$J$49,Data!$E$2:$E$49,$A32,Data!$C$2:$C$49,C$30) -> 82.1 | D32: =AVERAGEIFS(Data!$J$2:$J$49,Data!$E$2:$E$49,$A32,Data!$C$2:$C$49,D$30) -> 86.7 | E32: =AVERAGEIFS(Data!$J$2:$J$49,Data!$E$2:$E$49,$A32,Data!$C$2:$C$49,E$30) -> 90.4
A33: 3 | B33: =AVERAGEIFS(Data!$J$2:$J$49,Data!$E$2:$E$49,$A33,Data!$C$2:$C$49,B$30) -> 69.5 | C33: =AVERAGEIFS(Data!$J$2:$J$49,Data!$E$2:$E$49,$A33,Data!$C$2:$C$49,C$30) -> 74.8 | D33: =AVERAGEIFS(Data!$J$2:$J$49,Data!$E$2:$E$49,$A33,Data!$C$2:$C$49,D$30) -> 78.4 | E33: =AVERAGEIFS(Data!$J$2:$J$49,Data!$E$2:$E$49,$A33,Data!$C$2:$C$49,E$30) -> 81.7
A34: 4 | B34: =AVERAGEIFS(Data!$J$2:$J$49,Data!$E$2:$E$49,$A34,Data!$C$2:$C$49,B$30) -> 64.2 | C34: =AVERAGEIFS(Data!$J$2:$J$49,Data!$E$2:$E$49,$A34,Data!$C$2:$C$49,C$30) -> 68.9 | D34: =AVERAGEIFS(Data!$J$2:$J$49,Data!$E$2:$E$49,$A34,Data!$C$2:$C$49,D$30) -> 71.9 | E34: =AVERAGEIFS(Data!$J$2:$J$49,Data!$E$2:$E$49,$A34,Data!$C$2:$C$49,E$30) -> 74.8
A35: 5 | B35: =AVERAGEIFS(Data!$J$2:$J$49,Data!$E$2:$E$49,$A35,Data!$C$2:$C$49,B$30) -> 61.8 | C35: =AVERAGEIFS(Data!$J$2:$J$49,Data!$E$2:$E$49,$A35,Data!$C$2:$C$49,C$30) -> 65.2 | D35: =AVERAGEIFS(Data!$J$2:$J$49,Data!$E$2:$E$49,$A35,Data!$C$2:$C$49,D$30) -> 68.1 | E35: =AVERAGEIFS(Data!$J$2:$J$49,Data!$E$2:$E$49,$A35,Data!$C$2:$C$49,E$30) -> 70.9
A36: 6 | B36: =AVERAGEIFS(Data!$J$2:$J$49,Data!$E$2:$E$49,$A36,Data!$C$2:$C$49,B$30) -> 59.4 | C36: =AVERAGEIFS(Data!$J$2:$J$49,Data!$E$2:$E$49,$A36,Data!$C$2:$C$49,C$30) -> 62.4 | D36: =AVERAGEIFS(Data!$J$2:$J$49,Data!$E$2:$E$49,$A36,Data!$C$2:$C$49,D$30) -> 65.4 | E36: =AVERAGEIFS(Data!$J$2:$J$49,Data!$E$2:$E$49,$A36,Data!$C$2:$C$49,E$30) -> 68.1
A37: 7 | B37: =AVERAGEIFS(Data!$J$2:$J$49,Data!$E$2:$E$49,$A37,Data!$C$2:$C$49,B$30) -> 60.1 | C37: =AVERAGEIFS(Data!$J$2:$J$49,Data!$E$2:$E$49,$A37,Data!$C$2:$C$49,C$30) -> 63.1 | D37: =AVERAGEIFS(Data!$J$2:$J$49,Data!$E$2:$E$49,$A37,Data!$C$2:$C$49,D$30) -> 66.2 | E37: =AVERAGEIFS(Data!$J$2:$J$49,Data!$E$2:$E$49,$A37,Data!$C$2:$C$49,E$30) -> 69
A38: 8 | B38: =AVERAGEIFS(Data!$J$2:$J$49,Data!$E$2:$E$49,$A38,Data!$C$2:$C$49,B$30) -> 63.7 | C38: =AVERAGEIFS(Data!$J$2:$J$49,Data!$E$2:$E$49,$A38,Data!$C$2:$C$49,C$30) -> 66.8 | D38: =AVERAGEIFS(Data!$J$2:$J$49,Data!$E$2:$E$49,$A38,Data!$C$2:$C$49,D$30) -> 69.8 | E38: =AVERAGEIFS(Data!$J$2:$J$49,Data!$E$2:$E$49,$A38,Data!$C$2:$C$49,E$30) -> 72.7
A39: 9 | B39: =AVERAGEIFS(Data!$J$2:$J$49,Data!$E$2:$E$49,$A39,Data!$C$2:$C$49,B$30) -> 68.9 | C39: =AVERAGEIFS(Data!$J$2:$J$49,Data!$E$2:$E$49,$A39,Data!$C$2:$C$49,C$30) -> 71.5 | D39: =AVERAGEIFS(Data!$J$2:$J$49,Data!$E$2:$E$49,$A39,Data!$C$2:$C$49,D$30) -> 74.6 | E39: =AVERAGEIFS(Data!$J$2:$J$49,Data!$E$2:$E$49,$A39,Data!$C$2:$C$49,E$30) -> 77.6
A40: 10 | B40: =AVERAGEIFS(Data!$J$2:$J$49,Data!$E$2:$E$49,$A40,Data!$C$2:$C$49,B$30) -> 73.2 | C40: =AVERAGEIFS(Data!$J$2:$J$49,Data!$E$2:$E$49,$A40,Data!$C$2:$C$49,C$30) -> 76.9 | D40: =AVERAGEIFS(Data!$J$2:$J$49,Data!$E$2:$E$49,$A40,Data!$C$2:$C$49,D$30) -> 80.3 | E40: =AVERAGEIFS(Data!$J$2:$J$49,Data!$E$2:$E$49,$A40,Data!$C$2:$C$49,E$30) -> 83.6
A41: 11 | B41: =AVERAGEIFS(Data!$J$2:$J$49,Data!$E$2:$E$49,$A41,Data!$C$2:$C$49,B$30) -> 79.8 | C41: =AVERAGEIFS(Data!$J$2:$J$49,Data!$E$2:$E$49,$A41,Data!$C$2:$C$49,C$30) -> 83.4 | D41: =AVERAGEIFS(Data!$J$2:$J$49,Data!$E$2:$E$49,$A41,Data!$C$2:$C$49,D$30) -> 87.1 | E41: =AVERAGEIFS(Data!$J$2:$J$49,Data!$E$2:$E$49,$A41,Data!$C$2:$C$49,E$30) -> 90.6
A42: 12 | B42: =AVERAGEIFS(Data!$J$2:$J$49,Data!$E$2:$E$49,$A42,Data!$C$2:$C$49,B$30) -> 86.2 | C42: =AVERAGEIFS(Data!$J$2:$J$49,Data!$E$2:$E$49,$A42,Data!$C$2:$C$49,C$30) -> 90.1 | D42: =AVERAGEIFS(Data!$J$2:$J$49,Data!$E$2:$E$49,$A42,Data!$C$2:$C$49,D$30) -> 94 | E42: =AVERAGEIFS(Data!$J$2:$J$49,Data!$E$2:$E$49,$A42,Data!$C$2:$C$49,E$30) -> 97.9
A43: Months > 85% | B43: =COUNTIF(B31:B42,">85") -> 1 | C43: =COUNTIF(C31:C42,">85") -> 2 | D43: =COUNTIF(D31:D42,">85") -> 4 | E43: =COUNTIF(E31:E42,">85") -> 4

Sheet Correlation
A1: Unit 4 · Correlation matrix heat map (Pearson r) and significance
A2: Colour scale: red = −1, grey = 0, blue = +1
A4: r | B4: ER_Visits | C4: ICU_Util_Rate | D4: Pub_Health_Exp | E4: Pop_Density_Idx | F4: Vacc_Coverage | G4: Flu_Resp_Cases
A5: ER_Visits | B5: =CORREL(Data!$I$2:$I$49,Data!$I$2:$I$49) -> 1 | C5: =CORREL(Data!$I$2:$I$49,Data!$J$2:$J$49) -> 0.99645458 | D5: =CORREL(Data!$I$2:$I$49,Data!$K$2:$K$49) -> 0.99772628 | E5: =CORREL(Data!$I$2:$I$49,Data!$L$2:$L$49) -> 0.47286856 | F5: =CORREL(Data!$I$2:$I$49,Data!$M$2:$M$49) -> 0.42186539 | G5: =CORREL(Data!$I$2:$I$49,Data!$N$2:$N$49) -> 0.98759393
A6: ICU_Util_Rate | B6: =CORREL(Data!$J$2:$J$49,Data!$I$2:$I$49) -> 0.99645458 | C6: =CORREL(Data!$J$2:$J$49,Data!$J$2:$J$49) -> 1 | D6: =CORREL(Data!$J$2:$J$49,Data!$K$2:$K$49) -> 0.99136608 | E6: =CORREL(Data!$J$2:$J$49,Data!$L$2:$L$49) -> 0.41012692 | F6: =CORREL(Data!$J$2:$J$49,Data!$M$2:$M$49) -> 0.35805243 | G6: =CORREL(Data!$J$2:$J$49,Data!$N$2:$N$49) -> 0.99301223
A7: Pub_Health_Exp | B7: =CORREL(Data!$K$2:$K$49,Data!$I$2:$I$49) -> 0.99772628 | C7: =CORREL(Data!$K$2:$K$49,Data!$J$2:$J$49) -> 0.99136608 | D7: =CORREL(Data!$K$2:$K$49,Data!$K$2:$K$49) -> 1 | E7: =CORREL(Data!$K$2:$K$49,Data!$L$2:$L$49) -> 0.5018227 | F7: =CORREL(Data!$K$2:$K$49,Data!$M$2:$M$49) -> 0.45326942 | G7: =CORREL(Data!$K$2:$K$49,Data!$N$2:$N$49) -> 0.98298921
A8: Pop_Density_Idx | B8: =CORREL(Data!$L$2:$L$49,Data!$I$2:$I$49) -> 0.47286856 | C8: =CORREL(Data!$L$2:$L$49,Data!$J$2:$J$49) -> 0.41012692 | D8: =CORREL(Data!$L$2:$L$49,Data!$K$2:$K$49) -> 0.5018227 | E8: =CORREL(Data!$L$2:$L$49,Data!$L$2:$L$49) -> 1 | F8: =CORREL(Data!$L$2:$L$49,Data!$M$2:$M$49) -> 0.97301257 | G8: =CORREL(Data!$L$2:$L$49,Data!$N$2:$N$49) -> 0.34868759
A9: Vacc_Coverage | B9: =CORREL(Data!$M$2:$M$49,Data!$I$2:$I$49) -> 0.42186539 | C9: =CORREL(Data!$M$2:$M$49,Data!$J$2:$J$49) -> 0.35805243 | D9: =CORREL(Data!$M$2:$M$49,Data!$K$2:$K$49) -> 0.45326942 | E9: =CORREL(Data!$M$2:$M$49,Data!$L$2:$L$49) -> 0.97301257 | F9: =CORREL(Data!$M$2:$M$49,Data!$M$2:$M$49) -> 1 | G9: =CORREL(Data!$M$2:$M$49,Data!$N$2:$N$49) -> 0.30306456
A10: Flu_Resp_Cases | B10: =CORREL(Data!$N$2:$N$49,Data!$I$2:$I$49) -> 0.98759393 | C10: =CORREL(Data!$N$2:$N$49,Data!$J$2:$J$49) -> 0.99301223 | D10: =CORREL(Data!$N$2:$N$49,Data!$K$2:$K$49) -> 0.98298921 | E10: =CORREL(Data!$N$2:$N$49,Data!$L$2:$L$49) -> 0.34868759 | F10: =CORREL(Data!$N$2:$N$49,Data!$M$2:$M$49) -> 0.30306456 | G10: =CORREL(Data!$N$2:$N$49,Data!$N$2:$N$49) -> 1
A12: p-values (H0: ρ = 0), t = r·√((n−2)/(1−r²))
A13: p | B13: ER_Visits | C13: ICU_Util_Rate | D13: Pub_Health_Exp | E13: Pop_Density_Idx | F13: Vacc_Coverage | G13: Flu_Resp_Cases
A14: ER_Visits | B14: =IF(ABS(B5)>=0.999999,0,_xlfn.T.DIST.2T(ABS(B5)*SQRT(46/(1-B5^2)),46)) -> 0 | C14: =IF(ABS(C5)>=0.999999,0,_xlfn.T.DIST.2T(ABS(C5)*SQRT(46/(1-C5^2)),46)) -> 4.1496985e-51 | D14: =IF(ABS(D5)>=0.999999,0,_xlfn.T.DIST.2T(ABS(D5)*SQRT(46/(1-D5^2)),46)) -> 1.5360586e-55 | E14: =IF(ABS(E5)>=0.999999,0,_xlfn.T.DIST.2T(ABS(E5)*SQRT(46/(1-E5^2)),46)) -> 0.00068884235 | F14: =IF(ABS(F5)>=0.999999,0,_xlfn.T.DIST.2T(ABS(F5)*SQRT(46/(1-F5^2)),46)) -> 0.0028219174 | G14: =IF(ABS(G5)>=0.999999,0,_xlfn.T.DIST.2T(ABS(G5)*SQRT(46/(1-G5^2)),46)) -> 1.2260671e-38
A15: ICU_Util_Rate | B15: =IF(ABS(B6)>=0.999999,0,_xlfn.T.DIST.2T(ABS(B6)*SQRT(46/(1-B6^2)),46)) -> 4.1496985e-51 | C15: =IF(ABS(C6)>=0.999999,0,_xlfn.T.DIST.2T(ABS(C6)*SQRT(46/(1-C6^2)),46)) -> 0 | D15: =IF(ABS(D6)>=0.999999,0,_xlfn.T.DIST.2T(ABS(D6)*SQRT(46/(1-D6^2)),46)) -> 3.0553667e-42 | E15: =IF(ABS(E6)>=0.999999,0,_xlfn.T.DIST.2T(ABS(E6)*SQRT(46/(1-E6^2)),46)) -> 0.0037904492 | F15: =IF(ABS(F6)>=0.999999,0,_xlfn.T.DIST.2T(ABS(F6)*SQRT(46/(1-F6^2)),46)) -> 0.012464113 | G15: =IF(ABS(G6)>=0.999999,0,_xlfn.T.DIST.2T(ABS(G6)*SQRT(46/(1-G6^2)),46)) -> 2.3967981e-44
A16: Pub_Health_Exp | B16: =IF(ABS(B7)>=0.999999,0,_xlfn.T.DIST.2T(ABS(B7)*SQRT(46/(1-B7^2)),46)) -> 1.5360586e-55 | C16: =IF(ABS(C7)>=0.999999,0,_xlfn.T.DIST.2T(ABS(C7)*SQRT(46/(1-C7^2)),46)) -> 3.0553667e-42 | D16: =IF(ABS(D7)>=0.999999,0,_xlfn.T.DIST.2T(ABS(D7)*SQRT(46/(1-D7^2)),46)) -> 0 | E16: =IF(ABS(E7)>=0.999999,0,_xlfn.T.DIST.2T(ABS(E7)*SQRT(46/(1-E7^2)),46)) -> 0.00027924091 | F16: =IF(ABS(F7)>=0.999999,0,_xlfn.T.DIST.2T(ABS(F7)*SQRT(46/(1-F7^2)),46)) -> 0.0012152093 | G16: =IF(ABS(G7)>=0.999999,0,_xlfn.T.DIST.2T(ABS(G7)*SQRT(46/(1-G7^2)),46)) -> 1.6610028e-35
A17: Pop_Density_Idx | B17: =IF(ABS(B8)>=0.999999,0,_xlfn.T.DIST.2T(ABS(B8)*SQRT(46/(1-B8^2)),46)) -> 0.00068884235 | C17: =IF(ABS(C8)>=0.999999,0,_xlfn.T.DIST.2T(ABS(C8)*SQRT(46/(1-C8^2)),46)) -> 0.0037904492 | D17: =IF(ABS(D8)>=0.999999,0,_xlfn.T.DIST.2T(ABS(D8)*SQRT(46/(1-D8^2)),46)) -> 0.00027924091 | E17: =IF(ABS(E8)>=0.999999,0,_xlfn.T.DIST.2T(ABS(E8)*SQRT(46/(1-E8^2)),46)) -> 0 | F17: =IF(ABS(F8)>=0.999999,0,_xlfn.T.DIST.2T(ABS(F8)*SQRT(46/(1-F8^2)),46)) -> 6.0852124e-31 | G17: =IF(ABS(G8)>=0.999999,0,_xlfn.T.DIST.2T(ABS(G8)*SQRT(46/(1-G8^2)),46)) -> 0.015146059
A18: Vacc_Coverage | B18: =IF(ABS(B9)>=0.999999,0,_xlfn.T.DIST.2T(ABS(B9)*SQRT(46/(1-B9^2)),46)) -> 0.0028219174 | C18: =IF(ABS(C9)>=0.999999,0,_xlfn.T.DIST.2T(ABS(C9)*SQRT(46/(1-C9^2)),46)) -> 0.012464113 | D18: =IF(ABS(D9)>=0.999999,0,_xlfn.T.DIST.2T(ABS(D9)*SQRT(46/(1-D9^2)),46)) -> 0.0012152093 | E18: =IF(ABS(E9)>=0.999999,0,_xlfn.T.DIST.2T(ABS(E9)*SQRT(46/(1-E9^2)),46)) -> 6.0852124e-31 | F18: =IF(ABS(F9)>=0.999999,0,_xlfn.T.DIST.2T(ABS(F9)*SQRT(46/(1-F9^2)),46)) -> 0 | G18: =IF(ABS(G9)>=0.999999,0,_xlfn.T.DIST.2T(ABS(G9)*SQRT(46/(1-G9^2)),46)) -> 0.036271653
A19: Flu_Resp_Cases | B19: =IF(ABS(B10)>=0.999999,0,_xlfn.T.DIST.2T(ABS(B10)*SQRT(46/(1-B10^2)),46)) -> 1.2260671e-38 | C19: =IF(ABS(C10)>=0.999999,0,_xlfn.T.DIST.2T(ABS(C10)*SQRT(46/(1-C10^2)),46)) -> 2.3967981e-44 | D19: =IF(ABS(D10)>=0.999999,0,_xlfn.T.DIST.2T(ABS(D10)*SQRT(46/(1-D10^2)),46)) -> 1.6610028e-35 | E19: =IF(ABS(E10)>=0.999999,0,_xlfn.T.DIST.2T(ABS(E10)*SQRT(46/(1-E10^2)),46)) -> 0.015146059 | F19: =IF(ABS(F10)>=0.999999,0,_xlfn.T.DIST.2T(ABS(F10)*SQRT(46/(1-F10^2)),46)) -> 0.036271653 | G19: =IF(ABS(G10)>=0.999999,0,_xlfn.T.DIST.2T(ABS(G10)*SQRT(46/(1-G10^2)),46)) -> 0
A21: Two clusters: seasonal demand (ER, ICU, expenditure, flu; r ≥ 0.98) and structural trend (population density, vaccination; r = 0.97). Expenditure and ICU are outcomes of demand and are not used as regression predictors.

Sheet Decomposition
A1: Unit 6 · Classical decomposition of ER visits (period = 12)
A2: Trend = 2×12 centred moving average; seasonal index = average ratio-to-MA by month, normalised to mean 1 (multiplicative) or 0 (additive)
A4: Date | B4: t | C4: Month | D4: ER visits (Y) | E4: Trend: 2×12 CMA | F4: Ratio Y/CMA | G4: Y − CMA | H4: Seasonal index (mult) | I4: Deseasonalised Y/S | J4: Irregular (mult) | K4: Seasonal (add) | L4: Irregular (add) | M4: Irregular % | N4: Irregular z | O4: Mult irregular (visits) | Q4: Seasonal indices
A5: =Data!B2 -> 44197 | B5: 1 | C5: =MONTH(A5) -> 1 | D5: =Data!I2 -> 4820 | F5: =IF(E5="","",D5/E5) | G5: =IF(E5="","",D5-E5) | H5: =INDEX($S$6:$S$17,C5) -> 1.2492676 | I5: =D5/H5 -> 3858.2605 | J5: =IF(E5="","",D5/(E5*H5)) | K5: =INDEX($U$6:$U$17,C5) -> 1191.088 | L5: =IF(E5="","",D5-E5-K5) | M5: =IF(E5="","",(J5-1)*100) | N5: =IF(E5="","",(M5-AVERAGE($M$5:$M$52))/_xlfn.STDEV.S($M$5:$M$52)) | O5: =IF(E5="","",(J5-1)*E5) | Q5: Month | R5: Raw mult | S5: Normalised mult | T5: Raw add | U5: Normalised add
A6: =Data!B3 -> 44228 | B6: 2 | C6: =MONTH(A6) -> 2 | D6: =Data!I3 -> 4510 | F6: =IF(E6="","",D6/E6) | G6: =IF(E6="","",D6-E6) | H6: =INDEX($S$6:$S$17,C6) -> 1.1425117 | I6: =D6/H6 -> 3947.4432 | J6: =IF(E6="","",D6/(E6*H6)) | K6: =INDEX($U$6:$U$17,C6) -> 683.44907 | L6: =IF(E6="","",D6-E6-K6) | M6: =IF(E6="","",(J6-1)*100) | N6: =IF(E6="","",(M6-AVERAGE($M$5:$M$52))/_xlfn.STDEV.S($M$5:$M$52)) | O6: =IF(E6="","",(J6-1)*E6) | Q6: 1 | R6: =AVERAGEIF($C$5:$C$52,Q6,$F$5:$F$52) -> 1.2495665 | S6: =R6/AVERAGE($R$6:$R$17) -> 1.2492676 | T6: =AVERAGEIF($C$5:$C$52,Q6,$G$5:$G$52) -> 1192.2222 | U6: =T6-AVERAGE($T$6:$T$17) -> 1191.088
A7: =Data!B4 -> 44256 | B7: 3 | C7: =MONTH(A7) -> 3 | D7: =Data!I4 -> 4180 | F7: =IF(E7="","",D7/E7) | G7: =IF(E7="","",D7-E7) | H7: =INDEX($S$6:$S$17,C7) -> 1.0127776 | I7: =D7/H7 -> 4127.2635 | J7: =IF(E7="","",D7/(E7*H7)) | K7: =INDEX($U$6:$U$17,C7) -> 61.365741 | L7: =IF(E7="","",D7-E7-K7) | M7: =IF(E7="","",(J7-1)*100) | N7: =IF(E7="","",(M7-AVERAGE($M$5:$M$52))/_xlfn.STDEV.S($M$5:$M$52)) | O7: =IF(E7="","",(J7-1)*E7) | Q7: 2 | R7: =AVERAGEIF($C$5:$C$52,Q7,$F$5:$F$52) -> 1.142785 | S7: =R7/AVERAGE($R$6:$R$17) -> 1.1425117 | T7: =AVERAGEIF($C$5:$C$52,Q7,$G$5:$G$52) -> 684.58333 | U7: =T7-AVERAGE($T$6:$T$17) -> 683.44907
A8: =Data!B5 -> 44287 | B8: 4 | C8: =MONTH(A8) -> 4 | D8: =Data!I5 -> 3920 | F8: =IF(E8="","",D8/E8) | G8: =IF(E8="","",D8-E8) | H8: =INDEX($S$6:$S$17,C8) -> 0.92057255 | I8: =D8/H8 -> 4258.2195 | J8: =IF(E8="","",D8/(E8*H8)) | K8: =INDEX($U$6:$U$17,C8) -> -385.5787 | L8: =IF(E8="","",D8-E8-K8) | M8: =IF(E8="","",(J8-1)*100) | N8: =IF(E8="","",(M8-AVERAGE($M$5:$M$52))/_xlfn.STDEV.S($M$5:$M$52)) | O8: =IF(E8="","",(J8-1)*E8) | Q8: 3 | R8: =AVERAGEIF($C$5:$C$52,Q8,$F$5:$F$52) -> 1.0130199 | S8: =R8/AVERAGE($R$6:$R$17) -> 1.0127776 | T8: =AVERAGEIF($C$5:$C$52,Q8,$G$5:$G$52) -> 62.5 | U8: =T8-AVERAGE($T$6:$T$17) -> 61.365741
A9: =Data!B6 -> 44317 | B9: 5 | C9: =MONTH(A9) -> 5 | D9: =Data!I6 -> 3710 | F9: =IF(E9="","",D9/E9) | G9: =IF(E9="","",D9-E9) | H9: =INDEX($S$6:$S$17,C9) -> 0.86852134 | I9: =D9/H9 -> 4271.6279 | J9: =IF(E9="","",D9/(E9*H9)) | K9: =INDEX($U$6:$U$17,C9) -> -640.85648 | L9: =IF(E9="","",D9-E9-K9) | M9: =IF(E9="","",(J9-1)*100) | N9: =IF(E9="","",(M9-AVERAGE($M$5:$M$52))/_xlfn.STDEV.S($M$5:$M$52)) | O9: =IF(E9="","",(J9-1)*E9) | Q9: 4 | R9: =AVERAGEIF($C$5:$C$52,Q9,$F$5:$F$52) -> 0.92079277 | S9: =R9/AVERAGE($R$6:$R$17) -> 0.92057255 | T9: =AVERAGEIF($C$5:$C$52,Q9,$G$5:$G$52) -> -384.44444 | U9: =T9-AVERAGE($T$6:$T$17) -> -385.5787
A10: =Data!B7 -> 44348 | B10: 6 | C10: =MONTH(A10) -> 6 | D10: =Data!I7 -> 3580 | F10: =IF(E10="","",D10/E10) | G10: =IF(E10="","",D10-E10) | H10: =INDEX($S$6:$S$17,C10) -> 0.83238286 | I10: =D10/H10 -> 4300.9055 | J10: =IF(E10="","",D10/(E10*H10)) | K10: =INDEX($U$6:$U$17,C10) -> -821.13426 | L10: =IF(E10="","",D10-E10-K10) | M10: =IF(E10="","",(J10-1)*100) | N10: =IF(E10="","",(M10-AVERAGE($M$5:$M$52))/_xlfn.STDEV.S($M$5:$M$52)) | O10: =IF(E10="","",(J10-1)*E10) | Q10: 5 | R10: =AVERAGEIF($C$5:$C$52,Q10,$F$5:$F$52) -> 0.8687291 | S10: =R10/AVERAGE($R$6:$R$17) -> 0.86852134 | T10: =AVERAGEIF($C$5:$C$52,Q10,$G$5:$G$52) -> -639.72222 | U10: =T10-AVERAGE($T$6:$T$17) -> -640.85648
A11: =Data!B8 -> 44378 | B11: 7 | C11: =MONTH(A11) -> 7 | D11: =Data!I8 -> 3620 | E11: =(SUM(D5:D16)+SUM(D6:D17))/24 -> 4281.6667 | F11: =IF(E11="","",D11/E11) -> 0.84546516 | G11: =IF(E11="","",D11-E11) -> -661.66667 | H11: =INDEX($S$6:$S$17,C11) -> 0.84139027 | I11: =D11/H11 -> 4302.403 | J11: =IF(E11="","",D11/(E11*H11)) -> 1.004843 | K11: =INDEX($U$6:$U$17,C11) -> -734.05093 | L11: =IF(E11="","",D11-E11-K11) -> 72.384259 | M11: =IF(E11="","",(J11-1)*100) -> 0.48430405 | N11: =IF(E11="","",(M11-AVERAGE($M$5:$M$52))/_xlfn.STDEV.S($M$5:$M$52)) -> 2.1454417 | O11: =IF(E11="","",(J11-1)*E11) -> 20.736285 | Q11: 6 | R11: =AVERAGEIF($C$5:$C$52,Q11,$F$5:$F$52) -> 0.83258198 | S11: =R11/AVERAGE($R$6:$R$17) -> 0.83238286 | T11: =AVERAGEIF($C$5:$C$52,Q11,$G$5:$G$52) -> -820 | U11: =T11-AVERAGE($T$6:$T$17) -> -821.13426
A12: =Data!B9 -> 44409 | B12: 8 | C12: =MONTH(A12) -> 8 | D12: =Data!I9 -> 3790 | E12: =(SUM(D6:D17)+SUM(D7:D18))/24 -> 4342.9167 | F12: =IF(E12="","",D12/E12) -> 0.87268541 | G12: =IF(E12="","",D12-E12) -> -552.91667 | H12: =INDEX($S$6:$S$17,C12) -> 0.8729157 | I12: =D12/H12 -> 4341.7709 | J12: =IF(E12="","",D12/(E12*H12)) -> 0.99973618 | K12: =INDEX($U$6:$U$17,C12) -> -592.38426 | L12: =IF(E12="","",D12-E12-K12) -> 39.467593 | M12: =IF(E12="","",(J12-1)*100) -> -0.026381508 | N12: =IF(E12="","",(M12-AVERAGE($M$5:$M$52))/_xlfn.STDEV.S($M$5:$M$52)) -> -0.23442109 | O12: =IF(E12="","",(J12-1)*E12) -> -1.1457269 | Q12: 7 | R12: =AVERAGEIF($C$5:$C$52,Q12,$F$5:$F$52) -> 0.84159155 | S12: =R12/AVERAGE($R$6:$R$17) -> 0.84139027 | T12: =AVERAGEIF($C$5:$C$52,Q12,$G$5:$G$52) -> -732.91667 | U12: =T12-AVERAGE($T$6:$T$17) -> -734.05093
A13: =Data!B10 -> 44440 | B13: 9 | C13: =MONTH(A13) -> 9 | D13: =Data!I10 -> 4120 | E13: =(SUM(D7:D18)+SUM(D8:D19))/24 -> 4388.75 | F13: =IF(E13="","",D13/E13) -> 0.93876388 | G13: =IF(E13="","",D13-E13) -> -268.75 | H13: =INDEX($S$6:$S$17,C13) -> 0.94023262 | I13: =D13/H13 -> 4381.8944 | J13: =IF(E13="","",D13/(E13*H13)) -> 0.9984379 | K13: =INDEX($U$6:$U$17,C13) -> -280.16204 | L13: =IF(E13="","",D13-E13-K13) -> 11.412037 | M13: =IF(E13="","",(J13-1)*100) -> -0.15620953 | N13: =IF(E13="","",(M13-AVERAGE($M$5:$M$52))/_xlfn.STDEV.S($M$5:$M$52)) -> -0.83943698 | O13: =IF(E13="","",(J13-1)*E13) -> -6.8556457 | Q13: 8 | R13: =AVERAGEIF($C$5:$C$52,Q13,$F$5:$F$52) -> 0.87312451 | S13: =R13/AVERAGE($R$6:$R$17) -> 0.8729157 | T13: =AVERAGEIF($C$5:$C$52,Q13,$G$5:$G$52) -> -591.25 | U13: =T13-AVERAGE($T$6:$T$17) -> -592.38426
A14: =Data!B11 -> 44470 | B14: 10 | C14: =MONTH(A14) -> 10 | D14: =Data!I11 -> 4480 | E14: =(SUM(D8:D19)+SUM(D9:D20))/24 -> 4419.5833 | F14: =IF(E14="","",D14/E14) -> 1.0136702 | G14: =IF(E14="","",D14-E14) -> 60.416667 | H14: =INDEX($S$6:$S$17,C14) -> 1.0166416 | I14: =D14/H14 -> 4406.6659 | J14: =IF(E14="","",D14/(E14*H14)) -> 0.99707722 | K14: =INDEX($U$6:$U$17,C14) -> 79.00463 | L14: =IF(E14="","",D14-E14-K14) -> -18.587963 | M14: =IF(E14="","",(J14-1)*100) -> -0.29227806 | N14: =IF(E14="","",(M14-AVERAGE($M$5:$M$52))/_xlfn.STDEV.S($M$5:$M$52)) -> -1.4735345 | O14: =IF(E14="","",(J14-1)*E14) -> -12.917472 | Q14: 9 | R14: =AVERAGEIF($C$5:$C$52,Q14,$F$5:$F$52) -> 0.94045754 | S14: =R14/AVERAGE($R$6:$R$17) -> 0.94023262 | T14: =AVERAGEIF($C$5:$C$52,Q14,$G$5:$G$52) -> -279.02778 | U14: =T14-AVERAGE($T$6:$T$17) -> -280.16204
A15: =Data!B12 -> 44501 | B15: 11 | C15: =MONTH(A15) -> 11 | D15: =Data!I12 -> 4910 | E15: =(SUM(D9:D20)+SUM(D10:D21))/24 -> 4445 | F15: =IF(E15="","",D15/E15) -> 1.1046119 | G15: =IF(E15="","",D15-E15) -> 465 | H15: =INDEX($S$6:$S$17,C15) -> 1.1071271 | I15: =D15/H15 -> 4434.9017 | J15: =IF(E15="","",D15/(E15*H15)) -> 0.99772816 | K15: =INDEX($U$6:$U$17,C15) -> 508.03241 | L15: =IF(E15="","",D15-E15-K15) -> -43.032407 | M15: =IF(E15="","",(J15-1)*100) -> -0.22718402 | N15: =IF(E15="","",(M15-AVERAGE($M$5:$M$52))/_xlfn.STDEV.S($M$5:$M$52)) -> -1.1701876 | O15: =IF(E15="","",(J15-1)*E15) -> -10.09833 | Q15: 10 | R15: =AVERAGEIF($C$5:$C$52,Q15,$F$5:$F$52) -> 1.0168848 | S15: =R15/AVERAGE($R$6:$R$17) -> 1.0166416 | T15: =AVERAGEIF($C$5:$C$52,Q15,$G$5:$G$52) -> 80.138889 | U15: =T15-AVERAGE($T$6:$T$17) -> 79.00463
A16: =Data!B13 -> 44531 | B16: 12 | C16: =MONTH(A16) -> 12 | D16: =Data!I13 -> 5340 | E16: =(SUM(D10:D21)+SUM(D11:D22))/24 -> 4469.1667 | F16: =IF(E16="","",D16/E16) -> 1.1948536 | G16: =IF(E16="","",D16-E16) -> 870.83333 | H16: =INDEX($S$6:$S$17,C16) -> 1.195659 | I16: =D16/H16 -> 4466.1564 | J16: =IF(E16="","",D16/(E16*H16)) -> 0.99932643 | K16: =INDEX($U$6:$U$17,C16) -> 931.22685 | L16: =IF(E16="","",D16-E16-K16) -> -60.393519 | M16: =IF(E16="","",(J16-1)*100) -> -0.067356775 | N16: =IF(E16="","",(M16-AVERAGE($M$5:$M$52))/_xlfn.STDEV.S($M$5:$M$52)) -> -0.4253713 | O16: =IF(E16="","",(J16-1)*E16) -> -3.0102865 | Q16: 11 | R16: =AVERAGEIF($C$5:$C$52,Q16,$F$5:$F$52) -> 1.107392 | S16: =R16/AVERAGE($R$6:$R$17) -> 1.1071271 | T16: =AVERAGEIF($C$5:$C$52,Q16,$G$5:$G$52) -> 509.16667 | U16: =T16-AVERAGE($T$6:$T$17) -> 508.03241
A17: =Data!B14 -> 44562 | B17: 13 | C17: =MONTH(A17) -> 1 | D17: =Data!I14 -> 5620 | E17: =(SUM(D11:D22)+SUM(D12:D23))/24 -> 4492.9167 | F17: =IF(E17="","",D17/E17) -> 1.2508578 | G17: =IF(E17="","",D17-E17) -> 1127.0833 | H17: =INDEX($S$6:$S$17,C17) -> 1.2492676 | I17: =D17/H17 -> 4498.6357 | J17: =IF(E17="","",D17/(E17*H17)) -> 1.0012729 | K17: =INDEX($U$6:$U$17,C17) -> 1191.088 | L17: =IF(E17="","",D17-E17-K17) -> -64.00463 | M17: =IF(E17="","",(J17-1)*100) -> 0.12728986 | N17: =IF(E17="","",(M17-AVERAGE($M$5:$M$52))/_xlfn.STDEV.S($M$5:$M$52)) -> 0.48170796 | O17: =IF(E17="","",(J17-1)*E17) -> 5.7190271 | Q17: 12 | R17: =AVERAGEIF($C$5:$C$52,Q17,$F$5:$F$52) -> 1.195945 | S17: =R17/AVERAGE($R$6:$R$17) -> 1.195659 | T17: =AVERAGEIF($C$5:$C$52,Q17,$G$5:$G$52) -> 932.36111 | U17: =T17-AVERAGE($T$6:$T$17) -> 931.22685
